Workbook

Sheet 表單回覆 整合
A1: 姓名 | B1: 性別 | C1: 年齡 | D1: 目前居住縣市 | E1: 工作產業 / 學生請填就讀科系 | F1: 進「電影院」觀影頻率 | G1: 最近進電影院看的電影（數量不限） | H1: 喜歡的電影類型 （多選） | I1: 閱讀劇本前，知道下列哪些妖怪傳說？（可複選） | J1: 閱讀劇本前，是否知道台灣有曾經製作過「核彈」的這段歷史？ | K1: 你認為主角是誰？(單選) | L1: 你喜歡的角色？ (可複選) | M1: 承上題，你喜歡這些角色的原因？ | N1: 你最不喜歡的角色？(單選) | O1: 承上題，你不喜歡這個角色的原因？ | P1: 下列哪個妖怪的超能力對你來說不清楚、看不懂？(可複選) | Q1: 下列哪個妖怪的超能力對你來說，覺得最無聊、最普通？(單選) | R1: 下列哪個妖怪的超能力對你來說，覺得最喜歡、最酷？(單選) | S1: 你覺得「局長」的陰謀是什麼？他為什麼要計劃這個陰謀？ | T1: 閱讀劇本後，你最期待被拍攝出來的場面？或是在文字描繪上有讓你產生強烈的畫面感？ 請提供頁數/場次或具體情節。 | U1: 你是否有看不懂的情節/橋段？ 請說明頁數/場次或具體情節，以及你不理解的部分。 | V1: 劇本哪一段的情節讓你覺得無聊或拖沓？ 請說明頁數/場次或具體情節，以及你覺得拖沓的原因。 | W1: 你是否覺得劇本有哪些地方不合理/出戲的地方？ 請說明頁數/場次或具體情節，以及你覺得不合理/出戲的地方。 | X1: 你在劇本哪一場次，知道虎哥跟虎姑婆是情侶關係？(單選) | Y1: 你在劇本哪一場次，知道水蛇跟水男孩是母子關係？(單選) | Z1: 你覺得覺得小潔跟虎姑婆在哪一場次開始產生革命情感？(單選) | AA1: 在第113場，看到護理師出現在後山基地時，你是否會覺得不合理？ 請回答合理/不合理，並說明原因。 | AB1: 閱讀劇本時，你是否有聯想到其他電影? 請舉例說明 | AC1: 劇本喜愛程度 | AD1: 請用一句話說明，你覺得這個劇本在講述一個什麼故事？ | AE1: 閱讀劇本後，你是否會想進電影院觀看本片？ | AF1: 你是否願意推薦本片給親朋好友？ | AG1: 承上題，你會推薦本片的原因？(可複選) | AH1: 看完劇本後，你會期待這個「變形者宇宙 」的下一部續集或外傳嗎？會期待由哪個角色擔任主角？ | AI1: 你是否還有任何想要補充或分享的想法？
A2: 杜宥霖 | B2: 生理男 | C2: 31-35 | D2: 臺北市 | E2: 研究助理 | F2: 一週一次或以上 | G2: 人骨聖殿 | H2: 超級英雄片（如：Marvel、DC）, 動作片 (如：007、不可能的任務、玩命關頭), 科幻片, 奇幻冒險片（如：哈利波特系列、魔戒）, 動漫片, 喜劇片 | I2: 虎姑婆, 好鼻師, 白賊七, 狐仙 | J2: 是 | K2: 白賊七 | L2: 虎姑婆 | M2: 很強 | N2: 小潔 | O2: 很煩 | P2: 局長：幻術, 小潔：讀心術 | Q2: 水蛇、水男孩 | R2: 局長：幻術 | S2: 為了自己的利益 | T2: 69頁 | U2: 30頁 | V2: 120頁 | W2: 50頁 | X2: 序3：虎姑婆說自己懷孕後，白賊七說：「恭喜恭喜！以後不只兩隻老虎了嗎？」 | Y2: 場58：小潔告訴虎姑婆三人：「水男孩是我們之中最優秀的，水蛇對他的期望很高，我們也一直以為局長會選他當接班人。」白賊七說：「沒想到是這種望子成龍的心情救了我們」 | Z2: 場17：小潔在虎姑婆耳邊偷偷提醒她快逃。 | AA2: 合理 | AB2: 沒有 | AC2: 6 | AD2: 超能力大戰 | AE2: 是 | AF2: 是 | AG2: 動作場面, 劇情精彩 | AH2: 不會 | AI2: 沒有
A3: 林昭彥 | B3: 生理男 | C3: 41-45 | D3: 桃園市 | E3: 科技業 | F3: 半年一次 | G3: 動物方城市2 | H3: 超級英雄片（如：Marvel、DC）, 動作片 (如：007、不可能的任務、玩命關頭), 科幻片, 奇幻冒險片（如：哈利波特系列、魔戒）, 動漫片, 喜劇片 | I3: 虎姑婆, 好鼻師, 白賊七, 狐仙 | J3: 是 | K3: 虎姑婆 | L3: 虎姑婆, 白賊七, 好鼻師 | M3: 滿寫實的 | N3: 鄧小姐 | O3: 角色轉換滿突兀的，感覺是為了劇情轉折硬加進去的。 | P3: 我都理解 | Q3: 白賊七：匕首 | R3: 局長：幻術 | S3: 想要永生 | T3: 場39 | U3: Page 56，一聲高頻 ~ 烏鴉嘴這段 | V3: 無。 | W3: 鄧小姐的角色轉折太硬了，最後核彈殺狐仙也很怪，如果核彈對妖怪有用，何必塞嘴巴。 | X3: 序3：虎姑婆說自己懷孕後，白賊七說：「恭喜恭喜！以後不只兩隻老虎了嗎？」 | Y3: 場39：水蛇說：「憑什麼是你，我兒子才是最適合的」 | Z3: 場17：小潔在虎姑婆耳邊偷偷提醒她快逃。 | AA3: 不合理，前面寫是密道，護理師竟然知道怎麼進去 | AB3: 各種特異功能像 X-Men，劇情有點像不可能的任務一 | AC3: 7 | AD3: 一群有特異功能的妖怪阻止昔日長官為非作歹的故事。 | AE3: 是 | AF3: 是 | AG3: 動作場面, 特效程度, 妖怪傳說 | AH3: 拍得夠精彩的畫會期待，小潔。 | AI3: 劇情部分算老套，但搭上很多台灣獨有的傳說與場景，還算有新意。序1的黑幕字卡應該直接刪掉，透過後續劇情一點一滴的揭露，會讓人更好奇而看下去。鄧小姐的部分真的要再修改一下，滿多部分都像是為了串劇情硬生出來的人設。另外針對妖怪的定義，建議是能透過一些橋段的增加，讓定義的更嚴謹一點 (如果你們想拍續集的話)，劇本裡的妖怪更像是有特異功能的人類，但一般對於妖怪的認知應該是有能力幻化成人形的動植物或自然現象，本質上不太一樣。(例如：妖怪能跟人類生小孩? )
A4: 劉瑋澔 | B4: 生理男 | C4: 36-40 | D4: 臺北市 | E4: 網路科技業 | F4: 一個月一次 | G4: 陽光女子合唱團 | H4: 超級英雄片（如：Marvel、DC）, 動作片 (如：007、不可能的任務、玩命關頭), 刑偵片, 科幻片, 奇幻冒險片（如：哈利波特系列、魔戒）, 浪漫愛情片, 動漫片, 喜劇片 | I4: 虎姑婆, 好鼻師, 白賊七, 狐仙 | J4: 是 | K4: 虎姑婆 | L4: 白賊七, 鄧小姐 | M4: 滿幽默的... | N4: 水蛇 | O4: 能力有點強，但讓人很感到煩躁，感覺戲份有點太多 | P4: 局長：幻術, 水蛇、水男孩 | Q4: 蜥蜴 | R4: 白賊七：詛咒 | S4: 延年益壽；但感覺在中間有些安排會讓這個陰謀有點不明確或是過於薄弱 | T4: 其實多數的打鬥畫面，感覺都滿值得期待的 | U4: 如回信羅列 盲測對象「劉瑋澔」回覆 | V4: 如回信羅列 盲測對象「劉瑋澔」回覆 | W4: 如回信羅列 盲測對象「劉瑋澔」回覆 | X4: 序3：虎姑婆說自己懷孕後，白賊七說：「恭喜恭喜！以後不只兩隻老虎了嗎？」 | Y4: 場39：水蛇說：「憑什麼是你，我兒子才是最適合的」 | Z4: 場25：小潔焦急地試圖幫虎姑婆止血，虎姑婆伸手，輕輕覆蓋在小潔的手臂上。 | AA4: 如果這裡是個相對隱密荒廢，但過去是機密的地點，稍微有點太隨性了 | AB4: 有點類似反派英雄片，但少了一個真的還在當反派的配角或許有點可惜 | AC4: 7 | AD4: 標準反派英雄想要阻止更壞的人的故事 | AE4: 是 | AF4: 是 | AG4: 動作場面, 劇情精彩, 特效程度, 妖怪傳說 | AH4: 會，感覺白賊七可以拍個類似 deadpool 的路線（？） | AI4: 劇情本身滿不錯的，還有些反轉跟幻術的伏筆；但特效可能會是很關鍵的一點
A5: 林羿豪 | B5: 生理男 | C5: 36-40 | D5: 新北市 | E5: 電商 | F5: 三個月一次 | G5: 阿凡達 出神入化3 | H5: 超級英雄片（如：Marvel、DC）, 動作片 (如：007、不可能的任務、玩命關頭), 刑偵片, 科幻片, 奇幻冒險片（如：哈利波特系列、魔戒）, 動漫片, 喜劇片 | I5: 虎姑婆 | J5: 是 | K5: 虎姑婆 | L5: 白賊七, 好鼻師 | M5: 白賊七的設定聰明 而且是劇中相對搞笑輕鬆的人物 好鼻師一心想保護家人 但在大局中也是一個關鍵腳色 | N5: 蜥蜴 | O5: 相對比較平淡 沒有特別的個性 | P5: 我都理解 | Q5: 虎姑婆 | R5: 白賊七：詛咒 | S5: 讓自己能夠一直活下去並且擁有狐仙的能力 一開始用國外醫術延壽 後來要換一個新的軀體 | T5: 序13 | U5: 沒有 | V5: 不需要一直重播核爆之後玉珮的畫面 雖然可以一直提示觀眾最後玉珮的關鍵作用 但我覺得出現太多次會讓人感覺煩躁 | W5: 目前還可以 基本邏輯都還過得去 | X5: 序6：虎哥將綁著紅繩、色澤溫潤的古代玉佩拿給虎姑婆，並告訴她玉佩是保平安用的護身符 | Y5: 場58：小潔告訴虎姑婆三人：「水男孩是我們之中最優秀的，水蛇對他的期望很高，我們也一直以為局長會選他當接班人。」白賊七說：「沒想到是這種望子成龍的心情救了我們」 | Z5: 場39：虎姑婆問小潔為什麼幫她，小潔說因為虎姑婆不是壞人，她讀到虎姑婆心聲只是想好好活下去。 | AA5: 劇本內容並沒有明確指出養老院跟基地的距離 如果原本就鄰近 相對還好 如果超級遠 那就不合理 | AB5: X戰警 還沒看到局長要延壽的時候 有閃過局長會不會是X教授的感覺 | AC5: 8 | AD5: 怪獸們努力融入人類生活甚至成為真正人的故事 | AE5: 是 | AF5: 是 | AG5: 動作場面, 諜報野史, 妖怪傳說 | AH5: 期待 林投姐 或是 手指月亮會被割耳朵的故事創造出來的主角 | AI5: 劇本看起來情感戲的部分都還算不拖沓 正式拍攝剪輯的時候希望節奏能抓得快一些 真正的重點還是可以放在動作戲上 刺激感會是這部片的賣點 傳說故事類的東西 節奏慢會讓人把原本合理的地方 也看到變成不合理
A6: 李艷娟 | B6: 生理女 | C6: 26-30 | D6: 新北市 | E6: 學術研究與教育產業 | F6: 三個月一次 | G6: 動物方城市2、不可能的任務最終清算 | H6: 超級英雄片（如：Marvel、DC）, 動作片 (如：007、不可能的任務、玩命關頭), 奇幻冒險片（如：哈利波特系列、魔戒）, 浪漫愛情片, 喜劇片 | I6: 虎姑婆, 狐仙 | J6: 是 | K6: 虎姑婆 | L6: 虎姑婆, 白賊七 | M6: 虎姑婆在劇本裡給人感覺正直、勇敢；白賊七聰明、詛咒常失敗（或總是只有奇怪的咒語會成功）讓整部劇變得搞笑 | N6: 局長 | O6: 我沒有特別不喜歡哪個角色，如果根據劇情硬選出一位的話，我會選局長。局長在這部劇中是反派，為了不想被犧牲所以和狐仙締約，為了自己的私心害了很多人卻包裝成是為了世界和平 | P6: 我都理解 | Q6: 蜥蜴 | R6: 白賊七：詛咒 | S6: 局長想培養心智最堅定的人作為接班人，並在儀式中吃掉接班人完成交接。雖然局長說所有的陰謀都是為了防止世界被妖怪毀滅（如果要這麼做的話應該會在核爆後繼續追殺虎姑婆他們？），但我認為局長有一部分是想延續自己的生命、保護自己原有的權力。 | T6: 場75 | U6: 1. 場29 不太確定是因為好鼻師透過玉佩看到虎姑婆在ELT的經歷所以馬上相信招喚小孩這件事還是其他原因，覺得馬上聽信平板有問題回家找女兒有點倉促 2. 場38 看完劇本後，還是有點好奇跟著局長的妖怪們的動機或是成為接班人有什麼好處嗎？ 3. 場47 好奇選的五個地點有什麼特殊意義嗎 4. 場72 黃如萱為什麼要一起去開會？ 5. 場73 為什麼所有人要一起去故宮還帶著欣欣？ | V6: 無 | W6: 1. 場39 虎姑婆心情複雜但看到小潔傷感卻又尷尬，我覺得這裡的情緒好像有點無法銜接 2.場42 好鼻師和小潔並肩坐在沙發，有點不太能想像那個畫面，感覺他們應該沒有很熟不會這麼做？ | X6: 序6：虎哥將綁著紅繩、色澤溫潤的古代玉佩拿給虎姑婆，並告訴她玉佩是保平安用的護身符 | Y6: 場39：水蛇說：「憑什麼是你，我兒子才是最適合的」 | Z6: 場25：小潔焦急地試圖幫虎姑婆止血，虎姑婆伸手，輕輕覆蓋在小潔的手臂上。 | AA6: 不太合理，前面虎姑婆去找鄧小姐的時候護理師有提到「您又來了」（場46的最後），所以護理師應該認為鄧小姐時常有幻覺？所以應該會先阻止鄧小姐前往後山基地，而不是相信鄧小姐後跟著去又聽到鄧小姐提到核彈 | AB6: 無 | AC6: 8 | AD6: 這個劇本利用臺灣妖怪傳說描述了一群妖怪的故事，並在故事中用詼諧有趣與打鬥畫面帶出妖怪也是有情感、能融入人類社會的 | AE6: 是 | AF6: 是 | AG6: 動作場面, 情感真摯, 特效程度 | AH6: 會期待外傳（例如妖怪們遇見局長前的故事），對於主角沒有什麼特別的想法 | AI6: 無
A7: 吳香穎 | B7: 生理女 | C7: 31-35 | D7: 臺北市 | E7: 顧問業 | F7: 一個月一次 | G7: 大濛、國寶、換乘真愛、東京計程車、Marty Supreme | H7: 超級英雄片（如：Marvel、DC）, 動作片 (如：007、不可能的任務、玩命關頭), 科幻片, 奇幻冒險片（如：哈利波特系列、魔戒）, 浪漫愛情片, 文藝劇情片, 喜劇片 | I7: 虎姑婆, 狐仙 | J7: 否 | K7: 虎姑婆 | L7: 虎姑婆, 小潔 | M7: 個性正直磊落 | N7: 水蛇 | O7: 從文字看起來感覺很恐怖（有點像怪獸電力公司的反派 | P7: 白賊七：匕首, 蜥蜴 | Q7: 好鼻師：操控螞蟻 | R7: 白賊七：詛咒 | S7: 為了自己活命，將他的靈魂延續下去，找下一個軀殼（類似佛地魔？） | T7: 場六，p.19，虎姑婆與小潔互相接觸後啟動小潔的能力 | U7: 不理解整個故事核武的必要性 | V7: 場77-80，好鼻師帶著妻小離開，很明顯會再被抓走， | W7: 沒有說明為何需要利用狐仙，以及狐仙消氣的也太快了吧～狐仙算是仙還是妖？以及為什麼所有妖怪都怕局長？可以把妖怪之王打倒的究竟是什麼？ | X7: 序13：蜥蜴要引爆核彈之際，虎哥按住虎姑婆的肩膀，要她好好活下去後，毅然決然地犧牲自己。 | Y7: 場39：水蛇說：「憑什麼是你，我兒子才是最適合的」 | Z7: 場21：虎姑婆帶著小潔破窗逃生後，護住小潔自己先著地，導致傷口再度滲血。 | AA7: 不合理，鄧小姐有被下暗示所以不疑有他，但護理師怎麼會敢來這種地方 | AB7: 功夫熊貓～很多動物一起奮戰的感覺！ | AC7: 7 | AD7: 以妖怪傳說來講邪不勝正、人人平等（動物也是） | AE7: 是 | AF7: 是 | AG7: 特效程度, 妖怪傳說 | AH7: 會，蜥蜴（感覺他的視角會很有趣） | AI7: 期待動畫成品
A8: 阮奕安 | B8: 生理男 | C8: 26-30 | D8: 桃園市 | E8: 電商 | F8: 三個月一次 | G8: 換乘真愛, F1, 超人, 魔法壞女巫, 少年Pi的奇幻漂流(舞台劇的電影版) | H8: 超級英雄片（如：Marvel、DC）, 動作片 (如：007、不可能的任務、玩命關頭), 刑偵片, 科幻片, 奇幻冒險片（如：哈利波特系列、魔戒）, 浪漫愛情片, 動漫片, 喜劇片 | I8: 虎姑婆, 好鼻師, 白賊七, 狐仙 | J8: 是 | K8: 虎姑婆 | L8: 虎姑婆, 白賊七, 好鼻師 | M8: 三人都有明顯的個人魅力與能力 雖然是妖怪卻有人情味 | N8: 局長 | O8: 最大的反派角色 自私 | P8: 我都理解 | Q8: 虎姑婆 | R8: 白賊七：詛咒 | S8: 犧牲小傑和小孩們 為了延續自己壽命 | T8: 場39 打鬥畫面 場75 動作戲 場79 監視器都變成局長雙眼 | U8: 沒有特別印象 | V8: 沒有特別印象 | W8: 場47 白賊七說 只要得到Ａ 就能得到B的句型 這句話相對出戲 | X8: 序6：虎哥將綁著紅繩、色澤溫潤的古代玉佩拿給虎姑婆，並告訴她玉佩是保平安用的護身符 | Y8: 場58：小潔告訴虎姑婆三人：「水男孩是我們之中最優秀的，水蛇對他的期望很高，我們也一直以為局長會選他當接班人。」白賊七說：「沒想到是這種望子成龍的心情救了我們」 | Z8: 場21：虎姑婆帶著小潔破窗逃生後，護住小潔自己先著地，導致傷口再度滲血。 | AA8: 不合理 後山基地錯綜複雜 護理師不該能順利出現在大家面前 | AB8: 通靈少女 復仇者聯盟 和控制(遊戲) 超能力偏向一般人 不算是非常浮誇 拯救的事件 也不像是復仇者類型 毀天滅地 更像是接近民間 | AC8: 7 | AD8: 台灣民俗妖怪拯救災難發生 | AE8: 是 | AF8: 是 | AG8: 動作場面, 情感真摯, 妖怪傳說 | AH8: 會期待 下一次由小潔擔任主角或更多表現機會 | AI8: 題材滿有趣 很久沒看到台灣民俗妖怪為主角的電影 以及跟政府機密有關的內容 滿期待！
A9: 謝佩珊 | B9: 生理女 | C9: 31-35 | D9: 新北市 | E9: 數位行銷 | F9: 一個月一次 | G9: 雙囍/動物方程式/他年她日/ | H9: 超級英雄片（如：Marvel、DC）, 動作片 (如：007、不可能的任務、玩命關頭), 奇幻冒險片（如：哈利波特系列、魔戒） | I9: 虎姑婆, 白賊七, 狐仙 | J9: 否 | K9: 虎姑婆 | L9: 白賊七 | M9: 很帥氣、烏鴉嘴設定有趣 | N9: 蜥蜴 | O9: 設定滿單薄的 | P9: 好鼻師：氣味偵查, 小潔：讀心術, 蜥蜴 | Q9: 虎姑婆 | R9: 白賊七：詛咒 | S9: 不太懂前面佈置要殺妖怪的陰謀是什麼設定，跟最後需要找小潔、很多小孩的連結是什麼 但是有看懂原因是為了替換身體、讓狐仙長駐與局長一起 | T9: 1.閃回局長以前回憶，古代畫面。2. 故宮文物那段，感覺拍起來很有趣 | U9: 水男孩的能力初期有點看不懂，而且會不懂他跟水蛇的關係（可能也是水男孩的命名有點不懂） | V9: 1. 開頭回到現在時序，好鼻師在問虎姑婆還好嗎？虎姑婆不需要把過去爆炸發生的事件都講一遍，太解釋性了 2. 蒙太奇手法重現在隧道生活的片段，感覺很老套，而且這段時間這麼短應該也不用重現片段 | W9: 最後狐仙被虎姑婆一個眼神還有回憶就影響，然後掙脫離開了。有點太輕描淡寫解決問題 | X9: 序6：虎哥將綁著紅繩、色澤溫潤的古代玉佩拿給虎姑婆，並告訴她玉佩是保平安用的護身符 | Y9: 場39：水蛇說：「憑什麼是你，我兒子才是最適合的」 | Z9: 場25：小潔焦急地試圖幫虎姑婆止血，虎姑婆伸手，輕輕覆蓋在小潔的手臂上。 | AA9: 超不合理 | AB9: 沒有 | AC9: 6 | AD9: 妖怪隊伍、破散又重組，一起解決危機 | AE9: 否 | AF9: 是 | AG9: 劇情精彩, 情感真摯 | AH9: 白賊七 | AI9: 小潔的角色也覺得有點單薄、讀心能力不是關鍵，好像有跟沒有差不多
A10: 許若莉 | B10: 生理女 | C10: 26-30 | D10: 新北市 | E10: 餐飲業 | F10: 三個月一次 | G10: 大濛、陽光女子合唱團 | H10: 超級英雄片（如：Marvel、DC）, 動作片 (如：007、不可能的任務、玩命關頭), 奇幻冒險片（如：哈利波特系列、魔戒）, 浪漫愛情片, 恐怖片 | I10: 虎姑婆 | J10: 否 | K10: 虎姑婆 | L10: 白賊七, 小潔 | M10: 雖然不知道白賊七的故事，但詛咒能力很吸引人，他有能力可以傷害人，但他沒有，抽筋10分鐘滿有畫面的。小潔雖然被訓練洗腦很多年，但卻依然有著善良的心，像是被社會摧殘後，還能保有一顆溫暖的心，在現實生活中我們也期許自己是這樣的人吧～ | N10: 虎姑婆 | O10: 不是不喜歡，覺得虎姑婆的角色可以多一些背景故事，去闡述他的情感世界，目前看下來只覺得他就是生理女的直男。 | P10: 白賊七：匕首 | Q10: 虎姑婆 | R10: 白賊七：詛咒 | S10: 要讓自己獲得永生 | T10: 覺得期待好鼻師和白賊七啟動能力的情節被拍出來 | U10: 沒有 | V10: 沒有 | W10: 護理師出現在備用機地，雖然有點好笑，但就覺得這基地也不是很隱密嘛～ | X10: 序3：虎姑婆說自己懷孕後，白賊七說：「恭喜恭喜！以後不只兩隻老虎了嗎？」 | Y10: 場39：水蛇說：「憑什麼是你，我兒子才是最適合的」 | Z10: 場70：小潔告訴虎姑婆，被ELT帶走的育幼院孩子們之間有一個約定，最後活下來的人要代替所有人好好活下去，之後小潔將玉佩還給虎姑婆。 | AA10: 不合理 | AB10: 有點像韓劇的十二使者(講十二生肖的)，都是傳說故事中的人物，真實的活在現實生活中 | AC10: 7 | AD10: 人性的貪婪 讓我們總是想控制一切 | AE10: 是 | AF10: 是 | AG10: 妖怪傳說 | AH10: 會，白賊七 | AI10: 沒有
A11: 林哲毅 | B11: 生理男 | C11: 26-30 | D11: 臺北市 | E11: 醫療業 | F11: 一個月一次 | G11: 全知讀者視角 | H11: 超級英雄片（如：Marvel、DC）, 動作片 (如：007、不可能的任務、玩命關頭), 科幻片, 奇幻冒險片（如：哈利波特系列、魔戒）, 動漫片 | I11: 虎姑婆, 白賊七 | J11: 否 | K11: 虎姑婆 | L11: 好鼻師 | M11: 劇本中跟人類緊密感與親切感最明顯自然的角色 | N11: 水蛇 | O11: 對於水蛇希望孩子成為局長接班人的動機不明 | P11: 好鼻師：操控螞蟻, 白賊七：匕首 | Q11: 局長：幻術 | R11: 白賊七：詛咒 | S11: 想自己成為千古不死的妖帝 | T11: 場4 欣欣拿蛋糕給虎姑婆 | U11: 都還算可理解 | V11: 都還好 | W11: 場137 何朵用獸妖的互相理解就感化狐仙有點太輕而易舉了 | X11: 序6：虎哥將綁著紅繩、色澤溫潤的古代玉佩拿給虎姑婆，並告訴她玉佩是保平安用的護身符 | Y11: 場39：水蛇說：「憑什麼是你，我兒子才是最適合的」 | Z11: 場25：小潔焦急地試圖幫虎姑婆止血，虎姑婆伸手，輕輕覆蓋在小潔的手臂上。 | AA11: 不合理 但是幽默感爆棚 感覺有種鄧小姐溜多遠 護理師就跟多遠的使命感 | AB11: 幾乎漫威的所有電影 或是以惡棍為主的自殺突擊隊 去故宮搶草堂筆記 想到尼可拉斯凱吉的國家寶藏搶獨立宣言 | AC11: 7 | AD11: 妖怪也想透過努力 跟自己認可的對象 過自己喜歡的生活 | AE11: 是 | AF11: 是 | AG11: 情感真摯 | AH11: 給虎姑婆一個完整的故事跟戀愛曲線吧 也許能解釋連狐仙都認可他的釋懷 | AI11: 場3好鼻師家廚房 想試試看如果虎姑婆是直接用利爪刺一塊肉吃 但是欣欣幫大家切蛋糕的時候遞給虎姑婆的盤子上，有放我們常用的塑膠叉子 雖然虎姑婆不覺得自己能以妖怪之身與人類孩子相處 但是在欣欣眼裡 也許她一直都是個帥氣的大姊姊
A12: 許偉康 | B12: 生理男 | C12: 36-40 | D12: 桃園市 | E12: 工程師 | F12: 三個月一次 | G12: 陽光女子合唱團、阿凡達三 | H12: 超級英雄片（如：Marvel、DC）, 動作片 (如：007、不可能的任務、玩命關頭), 科幻片, 奇幻冒險片（如：哈利波特系列、魔戒）, 動漫片, 喜劇片 | I12: 虎姑婆, 白賊七, 狐仙 | J12: 是 | K12: 虎姑婆 | L12: 白賊七 | M12: 比較精明 | N12: 蜥蜴 | O12: 看起來比較狡詐 | P12: 我都理解 | Q12: 虎姑婆 | R12: 白賊七：詛咒 | S12: 長生不老 | T12: 場66後山基地廊道 | U12: 否 | V12: 很少看長劇本，看得有點疲乏 | W12: 否 | X12: 場23：虎姑婆的夢境中，看到虎哥溫柔照顧自己，但下一瞬間，她卻驚恐發現自己流產了 | Y12: 場39：水蛇說：「憑什麼是你，我兒子才是最適合的」 | Z12: 場17：小潔在虎姑婆耳邊偷偷提醒她快逃。 | AA12: 是，沒交代清楚鄧小姐跟護理師的突然出現 | AB12: 劇情普通，感覺有類似的，但一時說不出來，只是時空背景換到東方台灣 | AC12: 3 | AD12: 妖怪在你我身邊的故事 | AE12: 是 | AF12: 否 | AG12: 不推薦 | AH12: 不要有續集了吧 | AI12: 無
A13: 謝麗菁 | B13: 生理女 | C13: 41-45 | D13: 新北市 | E13: 自由接案（娛樂唱片） | F13: 半年一次 | G13: 女孩 | H13: 超級英雄片（如：Marvel、DC）, 動作片 (如：007、不可能的任務、玩命關頭), 刑偵片, 奇幻冒險片（如：哈利波特系列、魔戒）, 浪漫愛情片, 文藝劇情片, 動漫片, 喜劇片 | I13: 虎姑婆 | J13: 否 | K13: 虎姑婆 | L13: 虎姑婆, 小潔 | M13: 勇敢 | N13: 局長 | O13: 自私 | P13: 白賊七：匕首 | Q13: 蜥蜴 | R13: 小潔：讀心術 | S13: 想永生 | T13: 序13 | U13: 無 | V13: 劇本目前看來都蠻拖沓的，會有點看不下去，一直中斷。 | W13: 鄧小姐後面變情報員出現的部分。有點莫名。 還有進故宮搶真跡，現在很多網路或故宮商店應該都有複製品，最後還損壞真跡。 | X13: 序3：虎姑婆說自己懷孕後，白賊七說：「恭喜恭喜！以後不只兩隻老虎了嗎？」 | Y13: 場39：水蛇說：「憑什麼是你，我兒子才是最適合的」 | Z13: 場38：虎姑婆在好鼻師暴怒詢問小潔，以及水蛇出現要劫走小潔時，擋在小潔身前保護她。 | AA13: 不合理，護理師也能找到？局長找不到？ | AB13: 無 | AC13: 6 | AD13: 自私人類藉由職務之便利用妖怪能力方便自己成事。 | AE13: 是 | AF13: 否 | AG13: 看看這個劇本畫面如何呈現。 | AH13: 無，目前看起來故事有點薄弱，想不到還能續集。 | AI13: 沒有，謝謝
... A23: 趙珩宇 | B23: 生理男 | C23: 31-35 | D23: 臺北市 | E23: 教師 | F23: 三個月一次 | G23: 前幾天看什麼女孩的 | H23: 超級英雄片（如：Marvel、DC）, 動作片 (如：007、不可能的任務、玩命關頭), 刑偵片, 科幻片, 奇幻冒險片（如：哈利波特系列、魔戒）, 浪漫愛情片, 文藝劇情片, 恐怖片, 動漫片, 喜劇片 | I23: 虎姑婆, 好鼻師, 白賊七, 狐仙 | J23: 是 | K23: 虎姑婆 | L23: 小潔 | M23: 覺得她的出現比較能讓人理解發生什麼事情，，當然他也是唯一知道事情來龍去脈的人，但這個角色就是可以讓人得到答案的人。 | N23: 好鼻師 | O23: 小配角 😅 | P23: 我都理解 | Q23: 水蛇、水男孩 | R23: 小潔：讀心術 | S23: 長生不死，找替身 | T23: 我比較想看到一開始的打鬥畫面，如果夠完美的話，可以幫後面他們的特殊能力的討論、定義解決很多問題。 | U23: 還好 | V23: 不會到無聊，但就後面任務一多，就有點海賊王的感覺 🤔 | W23: 好鼻師太多積累需要照顧，像是故宮的部分，打鬥前還要先安排家人，但他們在前面佈局的時候又可以互相看一眼就知道彼此該做的事情，但照顧其他人反而還要口說 🤔 | X23: 場5：虎姑婆取出蛋糕放在虎哥的照片前，幫他慶生。 | Y23: 場39：水蛇說：「憑什麼是你，我兒子才是最適合的」 | Z23: 當一開始她讀到虎姑婆記憶時，就多少產生一點關聯感 | AA23: 鄧小姐進來本來就很突兀了 🤣 後面有護理師追應該也還可以 | AB23: 中間突然穿插的無厘頭內容，有近十年國片的感覺 | AC23: 5 | AD23: 想帶出張憲義的事情吧？ | AE23: 是 | AF23: 是 | AG23: 諜報野史 | AH23: 不確定，要看拍出來的感覺 | AI23: 無
A24: 盧晉德 | B24: 生理男 | C24: 26-30 | D24: 新北市 | E24: 生技 | F24: 一個月一次 | G24: Mygo總集篇 | H24: 動作片 (如：007、不可能的任務、玩命關頭), 恐怖片, 動漫片 | I24: 虎姑婆, 好鼻師, 白賊七, 狐仙 | J24: 否 | K24: 虎姑婆 | L24: 小潔 | M24: 很貼近童年回憶 | N24: 虎哥 | O24: 無 | P24: 我都理解 | Q24: 蜥蜴 | R24: 局長：幻術 | S24: 無 | T24: 42 | U24: 無 | V24: 無 | W24: 無 | X24: 序13：蜥蜴要引爆核彈之際，虎哥按住虎姑婆的肩膀，要她好好活下去後，毅然決然地犧牲自己。 | Y24: 場56：小潔說：「只要你帶我回去，你兒子就永遠只是接班人的備用品」，水蛇對小潔和虎姑婆說：「我不會讓我兒子的努力白費的」 | Z24: 場21：虎姑婆帶著小潔破窗逃生後，護住小潔自己先著地，導致傷口再度滲血。 | AA24: 合理 | AB24: 無 | AC24: 4 | AD24: 妖魔故事 | AE24: 是 | AF24: 是 | AG24: 妖怪傳說 | AH24: 局長 | AI24: 無
A25: 施相宇 | B25: 生理男 | C25: 26-30 | D25: 新北市 | E25: 建築/營造 | F25: 半年一次 | G25: 阿煩答 火之燼（？ | H25: 超級英雄片（如：Marvel、DC）, 動作片 (如：007、不可能的任務、玩命關頭), 科幻片, 奇幻冒險片（如：哈利波特系列、魔戒）, 文藝劇情片, 恐怖片, 動漫片, 喜劇片 | I25: 虎姑婆 | J25: 否 | K25: 虎姑婆 | L25: 局長 | M25: 有帶入感 | N25: 蜥蜴 | O25: 不夠可愛（最近被迷音蜥蜴燒到 | P25: 我都理解 | Q25: 好鼻師：氣味偵查 | R25: 白賊七：詛咒 | S25: 還沒看完，但我猜是復興家族吧！ | T25: 場７, 在這個場景有許多動作畫面，可能因為我蠻喜歡各種風格的動作戲的關係，所以覺得這段蠻有畫面的 | U25: 依前後文還不至於不理解，看不懂直接自動轉換成伏筆 w | V25: 場123, 感覺幻術是這部劇很重要的一個元素，可以在空間轉換的部分多鋪陳一點，雖然可能有拖沓之嫌疑，但透過空間的轉換，作為劇情中的呼吸點感覺也不錯。 | W25: 可能因為時空背景的關係，只要不要太無中生有，都不會有不合理的感覺。 | X25: 場19：虎姑婆在幻術中，看到局長變成虎哥的模樣，溫柔地對她說：「你平安無事真是太好了，孩子人呢？」 | Y25: 場56：小潔說：「只要你帶我回去，你兒子就永遠只是接班人的備用品」，水蛇對小潔和虎姑婆說：「我不會讓我兒子的努力白費的」 | Z25: 場21：虎姑婆帶著小潔破窗逃生後，護住小潔自己先著地，導致傷口再度滲血。 | AA25: 感覺醫生、護士這類的角色，讓人覺得離死亡特別近，因此能看到其他存在，也是挺合理的。 | AB25: 比較少看台灣傳統文化的電影，所以沒有什麼聯想，就當成獨立世界在觀看。 | AC25: 7 | AD25: 異世界復興 | AE25: 是 | AF25: 是 | AG25: 諜報野史 | AH25: 還好 | AI25: 讚讚
A26: 張旭華 | B26: 生理女 | C26: 21-25 | D26: 臺北 | E26: 金融業 | F26: 三個月一次 | G26: 陽光少女合唱團 | H26: 超級英雄片（如：Marvel、DC）, 動作片 (如：007、不可能的任務、玩命關頭), 刑偵片, 科幻片, 奇幻冒險片（如：哈利波特系列、魔戒）, 恐怖片, 喜劇片 | I26: 虎姑婆, 狐仙 | J26: 否 | K26: 虎姑婆 | L26: 白賊七 | M26: 設定有趣 | N26: 好鼻師 | O26: 雖愛家但太懦弱 | P26: 我都理解 | Q26: 虎姑婆 | R26: 白賊七：詛咒 | S26: 延續壞蛋計畫 | T26: 虎姑婆 虎形打架 | U26: 沒有 | V26: 小孩子看平板 有點莫名奇妙的設定沒有講得很清楚 | W26: 虎姑婆莫名其妙突然對小潔有母愛心態 | X26: 場129：虎姑婆跟虎哥說：「這幾年我一直在想，如果任務順利結束，我們是不是就能找個地方，安靜地待著，遠離那些紛紛擾擾，好好地把孩子養大⋯就跟這裡一樣。」 | Y26: 場56：小潔說：「只要你帶我回去，你兒子就永遠只是接班人的備用品」，水蛇對小潔和虎姑婆說：「我不會讓我兒子的努力白費的」 | Z26: 場39：虎姑婆問小潔為什麼幫她，小潔說因為虎姑婆不是壞人，她讀到虎姑婆心聲只是想好好活下去。 | AA26: 不合理 莫名其妙 | AB26: X戰警 都是變種人跟人類的戰爭 也有一個組織 | AC26: 3 | AD26: 不同物種如何在同一片土地生存 | AE26: 否 | AF26: 否 | AG26: 動作場面, 妖怪傳說 | AH26: 如果拍得好的話 會 / 小潔 | AI26: 沒有
A27: 許哲維 | B27: 生理男 | C27: 36-40 | D27: 新北市 | E27: 金融業 | F27: 一個月一次 | G27: 陽光女子合唱團 | H27: 超級英雄片（如：Marvel、DC）, 動作片 (如：007、不可能的任務、玩命關頭), 奇幻冒險片（如：哈利波特系列、魔戒）, 動漫片, 喜劇片 | I27: 虎姑婆, 好鼻師, 狐仙 | J27: 是 | K27: 虎姑婆 | L27: 白賊七 | M27: 能力很有趣，在電影中可以發展性比較大，因為不是無敵的也可以鬧出笑話，像是最後救好鼻師女兒那邊，可以把抽筋十分鐘改成走路就扭到腳，畫面會更好笑 | N27: 蜥蜴 | O27: 既然是前期擔當叛徒的重要腳色，應該給他能力跟個性多點刻劃 | P27: 白賊七：匕首 | Q27: 水蛇、水男孩 | R27: 白賊七：詛咒 | S27: 要找到最適合的容器，轉移自己的靈魂，繼續活下去。不過做為大反派有點薄弱，我希望能改成他一直沒辦法用100%狐妖的力量，想要有小潔的能力來掌控狐妖力量，進一步殺光所有妖怪為童年身為容器的自己報仇。 | T27: 125/局長的回憶 | U27: 否 | V27: 89/故宮偷資料及後面那段，應該要說明局長沒空管他們的部分 | W27: 鄧小姐在大戰中出現的劇情太過出戲了，前面還算合理但最後那邊太突兀 | X27: 序6：虎哥將綁著紅繩、色澤溫潤的古代玉佩拿給虎姑婆，並告訴她玉佩是保平安用的護身符 | Y27: 場39：水蛇說：「憑什麼是你，我兒子才是最適合的」 | Z27: 場17：小潔在虎姑婆耳邊偷偷提醒她快逃。 | AA27: 不合理，剛看到會沒辦法聯想到為何 | AB27: 天降奇兵，也是妖怪集團，但沒有刻劃這麼深的情感，所以我覺得這劇本更勝一籌 | AC27: 9 | AD27: 面對自己的心結並救贖 | AE27: 是 | AF27: 是 | AG27: 劇情精彩, 情感真摯, 妖怪傳說 | AH27: 會，希望可以演另外一群妖怪在其他縣市發生的故事，最後在會合在一起 | AI27: 最後狐妖收得太簡單了，會讓看電影的人覺得虎頭蛇尾，還不如讓他看到虎姑婆救動物而受傷，進而透過狐妖殺死局長再離開
A28: 宋昆銘 | B28: 生理男 | C28: 46-50 | D28: 臺北市 | E28: 媒體出版業 | F28: 半年一次 | G28: 荒野機器人、侏羅紀公園重生 | H28: 超級英雄片（如：Marvel、DC）, 動作片 (如：007、不可能的任務、玩命關頭), 刑偵片, 科幻片, 奇幻冒險片（如：哈利波特系列、魔戒）, 動漫片, 喜劇片 | I28: 虎姑婆, 狐仙 | J28: 是 | K28: 虎姑婆 | L28: 虎姑婆, 小潔 | M28: 願意捨棄平靜追求真相 | N28: 水蛇 | O28: 形象過於扁平 | P28: 我都理解 | Q28: 白賊七：匕首 | R28: 局長：幻術 | S28: 更換軀體，繼續霸佔妖怪之王的能力 | T28: 利用能力戰鬥的場景或是基地等場景都有強烈畫面感 | U28: 水蛇被小潔威脅後立刻回頭殺掉手下 | V28: 鄧小姐的場景似乎有點多餘 | W28: 工業區育幼院的設定有點不自然 | X28: 序3：虎姑婆說自己懷孕後，白賊七說：「恭喜恭喜！以後不只兩隻老虎了嗎？」 | Y28: 場39：水蛇說：「憑什麼是你，我兒子才是最適合的」 | Z28: 場17：小潔在虎姑婆耳邊偷偷提醒她快逃。 | AA28: 不合理，可以找到基地太奇怪。 | AB28: 像是本土版的 JOJO 冒險野郎 | AC28: 6 | AD28: 套上本土文化的X戰警類型的故事 | AE28: 是 | AF28: 是 | AG28: 動作場面, 諜報野史, 妖怪傳說 | AH28: 這一集的角色群算是蠻用心的刻畫，如果有外傳的話，感覺詛咒之力其實比較有機會發揮。 | AI28: 虎姑婆應該要有隱藏的能力，最終 BOSS 戰時覺醒發動，可能更熱血。
A29: 莊仁豪 | B29: 生理男 | C29: 36-40 | D29: 臺北市 | E29: 醫療 | F29: 三個月一次 | G29: 陽光女子合唱團 | H29: 超級英雄片（如：Marvel、DC）, 動作片 (如：007、不可能的任務、玩命關頭), 奇幻冒險片（如：哈利波特系列、魔戒）, 動漫片 | I29: 虎姑婆, 好鼻師, 白賊七, 狐仙 | J29: 是 | K29: 虎姑婆 | L29: 鄧小姐 | M29: 出現時都富有喜感 | N29: 黃茹萱 | O29: 連結到現實有點出戲 | P29: 我都理解 | Q29: 白賊七：匕首 | R29: 蜥蜴 | S29: 找接班人; 沒有族人了 | T29: 場137 妖狐出世 | U29: 場139 白賊七老婆有年輕40歲嗎? | V29: 場80 好鼻師要帶家人離開那段覺得多餘 | W29: 場56, 水蛇幹嘛不把小潔殺了就好，局長也不會知道他殺的 | X29: 序3：虎姑婆說自己懷孕後，白賊七說：「恭喜恭喜！以後不只兩隻老虎了嗎？」 | Y29: 場39：水蛇說：「憑什麼是你，我兒子才是最適合的」 | Z29: 場21：虎姑婆帶著小潔破窗逃生後，護住小潔自己先著地，導致傷口再度滲血。 | AA29: 不覺得不合理，鄧小姐腳色感覺是戰情室一員，護理師是照護他的腳色 | AB29: X-men | AC29: 8 | AD29: 野心家的陰謀跟被壓迫的族人努力展開新生 | AE29: 是 | AF29: 是 | AG29: 諜報野史, 妖怪傳說 | AH29: 妖狐 | AI29: 初看劇本時第一個想法是妖怪的設定有點彆扭，除了虎姑婆較可以想像為老虎成精後的變化之外，其餘主角白賊七跟好鼻師都比較難跟妖怪做連結，比較像奇人異事而不是習慣上理解的妖怪，加之妖怪們除了有能力之外其餘似乎皆與常人無異，更難以帶入這個設定，整個感覺跟X-MEN之類的很類似(或各種有能力設定的故事海賊王、獵人之類)。或者是”妖怪”這個詞的關係，妖怪感覺起來是由各種五花八門的理由所形成，想像起來如果是”妖族”、”魔族”之類是個統一的群體，雖然設定基本上是沒有不同，但個人主觀上彆扭感比較少。
A30: 吳政鴻 | B30: 生理男 | C30: 41-45 | D30: 桃園市 | E30: 資訊業 | F30: 一年一次 | G30: 不可能的任務：最終清算 | H30: 超級英雄片（如：Marvel、DC）, 動作片 (如：007、不可能的任務、玩命關頭), 刑偵片, 科幻片, 奇幻冒險片（如：哈利波特系列、魔戒）, 浪漫愛情片, 文藝劇情片, 動漫片, 喜劇片, 歌舞片、紀錄片等 | I30: 虎姑婆, 狐仙 | J30: 是 | K30: 虎姑婆 | L30: 白賊七, 好鼻師 | M30: 超能力比較特別、讀起劇本比較有畫面感 | N30: 鄧小姐 | O30: 覺得影射鄧麗君小姐的成分太高，不是那麼尊重故人 | P30: 白賊七：匕首 | Q30: 虎姑婆 | R30: 白賊七：詛咒 | S30: 他的陰謀就是想長生不老、一直活下去，所以把老族長跟族人都趕盡殺絕；想要把小潔吃掉後利用她的能力重返青春健康。 | T30: 中了幻術與真實場景對比的段落都會比較期待，想看看最終電影的畫面詮釋是否有吸引力且合理。 | U30: 基本上沒有 | V30: 好鼻師跟太太與女兒一起和解的段落有點太肥皂劇了，感覺有點多餘且太輕鬆了（真的這麼容易相互理解那麼妖怪也不需要一直躲躲藏藏、現實上也不會有這麼多家庭問題） | W30: 一開始的對妖怪的說明有點太籠統，不是那麼的深入，而且個人覺得主角們（虎姑婆、白賊七、好鼻師等人）雖然都有出現在台灣的民間故事裡，但好像各自的故事發展彼此不相干，有些硬湊在一起的感覺（水蛇、蜥蜴好像是因為超能力符合故事需要所以被加進來的？就無所謂是不是台灣的民俗故事出身？）；另外最後狐仙從水男孩身體中被釋放出來，最後居然跟虎姑婆相互理解後平靜地跑掉了？？依照劇本所言，可以封印祂的族人已經滅亡了，照理說祂可以想做什麼就做什麼，而且活了一千年被關這麼久，一個瞬間就原諒一切，個人覺得有點太簡單了：故事一開始的說明煞有其事，有種重重拿起、最終輕輕放下的不合理感。 | X30: 序3：虎姑婆說自己懷孕後，白賊七說：「恭喜恭喜！以後不只兩隻老虎了嗎？」 | Y30: 場38水蛇出場的時候：因為在場17水男孩就用過相同的水刃招式 | Z30: 場16：小潔在電梯中，直視虎姑婆的眼睛跟她說，囚禁他們的，是同一個人。 | AA30: 會，覺得常跑到後山基地這個設定太牽強了，而且一般養老院的護理師應該不會像貼身私人醫護一樣（設定可以調整？） | AB30: 人物設定像是漫威的X戰警系列，有些場景會聯想到美國隊長或復仇者系列等 | AC30: 6 | AD30: 想要融合台灣民俗、民國政府核彈發展野史並實現個人正義並且與現實對抗的英雄故事 | AE30: 是 | AF30: 否 | AG30: 如果看了覺得不錯當然會推薦：根據劇本，很多場景的成敗與拍攝手法以及動畫製作的細膩度有高度關係。 | AH30: 狐仙當主角，跟中國或是日本的妖怪聯動之類的。 | AI30: 設定的部分可以再細膩一些： 1. 例如故事一開始的說明有點薄弱 2. 後段描述小局長跟狐仙借力量，把老族長殺了的段落，就是在看火影忍者跟人柱力呀~ 而且狐仙被關這麼久，不會跟歷代的承載者談條件嗎？ 劇本的拼湊感或是既視感很重，需要把獨特的設定巧思或特色呈現出來，不然會變得像在東施效顰。
A31: 丁展譽 | B31: 生理男 | C31: 36-40 | D31: 台北市 | E31: 科技 / 新創 / 網路 / 行銷 | F31: 一週一次或以上 | G31: 雙囍、大濛、陽光女子、Marty Supreme、冠軍之路、Send Help | H31: 超級英雄片（如：Marvel、DC）, 動作片 (如：007、不可能的任務、玩命關頭), 刑偵片, 科幻片, 奇幻冒險片（如：哈利波特系列、魔戒）, 浪漫愛情片, 文藝劇情片, 恐怖片, 動漫片, 喜劇片 | I31: 虎姑婆, 好鼻師, 白賊七, 狐仙 | J31: 是 | K31: 虎姑婆 | L31: 白賊七, 鄧小姐 | M31: 白賊七的詛咒能力很酷，雖然是智力擔當但性格偶爾有點傻萌，這個反差感很棒；是個存在感很強的角色。 很喜歡老年鄧小姊的再次出場，是讓人安心又可靠的帥氣老太太。 | N31: 水男孩 | O31: 就是個討厭的小屁孩 | P31: 我都理解 | Q31: 虎姑婆 | R31: 白賊七：詛咒 | S31: 恐懼死亡、想要永遠活著，本質上他已經算是妖怪之王了吧。 | T31: 動作場景都蠻期待的 場41-42（跟白賊七重逢）與場74-75（故宮）這兩段感覺也是畫面呈現會有很有趣的段落 | U31: 都看得懂 | V31: 沒有特別覺得無聊的段落 | W31: 有些用詞太有現代感，例如「閨蜜」「境外勢力」等等，體感會覺得不像是1988年會出現的字 | X31: 序6：虎哥將綁著紅繩、色澤溫潤的古代玉佩拿給虎姑婆，並告訴她玉佩是保平安用的護身符 | Y31: 場58：小潔告訴虎姑婆三人：「水男孩是我們之中最優秀的，水蛇對他的期望很高，我們也一直以為局長會選他當接班人。」白賊七說：「沒想到是這種望子成龍的心情救了我們」 | Z31: 場39：虎姑婆問小潔為什麼幫她，小潔說因為虎姑婆不是壞人，她讀到虎姑婆心聲只是想好好活下去。 | AA31: 還好，雖然不太合理但把它當成一個喜劇橋段來看，好像也沒必要太深究 | AB31: 虎姑婆的強悍打鬥角色形象有不死軍團的感覺 好鼻師的螞蟻戰甲會想到鋼鐵人+Spawn 白賊七的詛咒能力像咒術迴戰裡的咒言師狗卷 訓練設施、篩選兒童的部分就很有許多日本動漫作品的影子 | AC31: 8 | AD31: 一群半人半妖的王道冒險故事 | AE31: 是 | AF31: 是 | AG31: 動作場面, 劇情精彩, 特效程度, 妖怪傳說 | AH31: 會的，好奇白賊七躲避的40年發生了什麼事，另外，如果妖怪的能力會繼承（水男孩），那也會蠻想知道好鼻師的女兒覺醒後的發展 | AI31: 劇本整體讀起來很流暢，也很有畫面感
A32: 謝嘉芫 | B32: 生理男 | C32: 31-35 | D32: 新北市 | E32: 廣告行銷 | F32: 三個月一次 | G32: 冠軍之路、鬼滅之刃無限城、排球少年垃圾場的決戰 | H32: 超級英雄片（如：Marvel、DC）, 動漫片 | I32: 虎姑婆, 白賊七 | J32: 否 | K32: 虎姑婆 | L32: 白賊七 | M32: 白賊七的能力蠻帥，在關鍵劇情也有起到作用 | N32: 小潔 | O32: 沒有共鳴，也不了解角色動機 | P32: 好鼻師：操控螞蟻, 白賊七：匕首 | Q32: 虎姑婆 | R32: 白賊七：詛咒 | S32: 靠狐仙幫助自己，不想要繼承家族的遺志 | T32: 44頁左右，虎姑婆等人駕車逃離水蛇，有追打最後驚險逃脫成功，有畫面感。 場97，蜥蜴跟白賊七對決，白賊七最後智取 | U32: 為什麼小潔特別厲害（天生神力 chosen one ? | V32: 都還ok | W32: 小潔跟虎姑婆之間太快有革命情感了，而且小潔這個角色單薄，對比其他人都是有典故的妖怪，她好像純粹為了推進劇情用，沒有記憶點也沒有喜歡上這角色。 | X32: 場23：虎姑婆的夢境中，看到虎哥溫柔照顧自己，但下一瞬間，她卻驚恐發現自己流產了 | Y32: 場39：水蛇說：「憑什麼是你，我兒子才是最適合的」 | Z32: 場38：虎姑婆在好鼻師暴怒詢問小潔，以及水蛇出現要劫走小潔時，擋在小潔身前保護她。 | AA32: 沒感覺，覺得不是特別重要的角色，只當作讓鄧奶奶退場的小橋段。（但我很喜歡鄧奶奶原來是特務，開頭第一幕戲的角色竟然還有功能，第一次看到蠻驚喜的） | AB32: 早期的雷神索爾、美國隊長、蟻人等等，英雄的起源故事。 | AC32: 7 | AD32: 虎姑婆解決了一個一直困在自己心裡已久的疑問與心魔（當初到底發生什麼事？怎麼結束的？為什麼突然變成這樣） | AE32: 是 | AF32: 否 | AG32: 動作場面 | AH32: 不特別，沒有特別聯想還會有什麼傳說故事的可能性。因為角色的故事都收尾了，對於能怎麼擴張沒有想像力。 | AI32: 好不好看可能取決於動作場面與特效。三個英雄最喜歡白賊七的能力，好鼻師就能力如其名不意外（但我還是不知道為什麼他會用螞蟻，其實有歷史典故嗎？）虎姑婆的最普通，就是力量型角色而已，沒吸引人。其次是情感訴求不明，虎姑婆在意的事情好像沒辦法引起我的共鳴，就是有沒有解決最終魔王、他有沒有跟自己的過去和解看完都不太在意。反派的名氣也顯得比較小（水蛇、蜥蜴），跟主角群的名氣有點不匹配？最後是沒有感受出小潔這個角色的魅力，只作為推進劇情的小跟班用途。
A33: 陳巧孟 | B33: 生理女 | C33: 26-30 | D33: 台中市 | E33: 房地產 | F33: 三個月一次 | G33: 大濛、左撇子女孩、女孩 | H33: 超級英雄片（如：Marvel、DC）, 奇幻冒險片（如：哈利波特系列、魔戒）, 文藝劇情片, 動漫片 | I33: 虎姑婆, 白賊七, 狐仙 | J33: 否 | K33: 虎姑婆 | L33: 虎姑婆, 白賊七 | M33: 白賊七的腳色前面會以為是很兩光幽默的感覺，後續出現的反差感，詞裡留的伏筆、計畫邏輯帶領其他妖怪的過程 | N33: 水男孩 | O33: 因他自己的忌妒蒙蔽即無法思考看待局長做這些事情的意義與真實了 | P33: 白賊七：匕首 | Q33: 白賊七：匕首 | R33: 白賊七：詛咒 | S33: 局長年邁加上身體條件越來越差，策劃ELT未來菁英班、收購育幼院成訓練所，來找尋精神韌性高的學童，以靈換靈，截獲新生。 | T33: 場75，在故宮竊取手稿 | U33: 無 | V33: 場113，鄧小姐與看護出現的不太合理{老是開溜，會跑來這裡}，及過程對劇情進展不大，像是過場 | W33: 同上題 | X33: 序6：虎哥將綁著紅繩、色澤溫潤的古代玉佩拿給虎姑婆，並告訴她玉佩是保平安用的護身符 | Y33: 場39：水蛇說：「憑什麼是你，我兒子才是最適合的」 | Z33: 場21：虎姑婆帶著小潔破窗逃生後，護住小潔自己先著地，導致傷口再度滲血。 | AA33: 不合理/戰情室這麼簡單就可以讓鄧小姐與看護常進出?? | AB33: 西遊記 | AC33: 8 | AD33: 民間故事的人物與能力試著融入人類世界，好好活下去，維持平衡。 | AE33: 是 | AF33: 是 | AG33: 劇情精彩, 妖怪傳說 | AH33: 虎哥 | AI33: 無
A34: 郭冠璟 | B34: 生理女 | C34: 21-25 | D34: 新北市 | E34: 法律系 | F34: 一個月一次 | G34: 阿凡達3、大濛、陽光女子合唱團 | H34: 超級英雄片（如：Marvel、DC）, 動作片 (如：007、不可能的任務、玩命關頭), 刑偵片, 科幻片, 奇幻冒險片（如：哈利波特系列、魔戒）, 浪漫愛情片, 文藝劇情片, 動漫片, 喜劇片 | I34: 虎姑婆, 狐仙 | J34: 否 | K34: 虎姑婆 | L34: 虎姑婆, 白賊七, 小潔 | M34: 白賊七的咒術不適每次都成功有笑點、虎姑婆很灑脫很正義、小潔很聰明靈動 | N34: 蜥蜴 | O34: 壞人身邊的走狗 還虛偽的叫學長姊 | P34: 我都理解 | Q34: 蜥蜴 | R34: 白賊七：詛咒 | S34: 利用意識是轉換到精神韌性最強的小孩身上讓自己能夠永遠的活著並且繼續獲得狐仙的幻術 | T34: 蜥蜴按下炸彈核彈爆發虎姑婆胸前的玉珮吸收核彈能量的那瞬間特別有畫面感 | U34: 不理解為何中山樓是最適合擺祭壇的地方 | V34: 無 | W34: 後山基地如果離療養院很遠的話 鄧小姐如何自己常常跑去後山基地的 護理師又是如何知道鄧小姐會去的然後還找到這個地點 畢竟這個地點藏有很多軍事秘密 不可能是容易被發現的地方 | X34: 序6：虎哥將綁著紅繩、色澤溫潤的古代玉佩拿給虎姑婆，並告訴她玉佩是保平安用的護身符 | Y34: 場39：水蛇說：「憑什麼是你，我兒子才是最適合的」 | Z34: 場25：小潔焦急地試圖幫虎姑婆止血，虎姑婆伸手，輕輕覆蓋在小潔的手臂上。 | AA34: 不合理 後山基地如果離療養院很遠的話 鄧小姐如何自己常常跑去後山基地的 護理師又是如何知道鄧小姐會去的然後還找到這個地點 畢竟這個地點藏有很多軍事秘密 不可能是容易被發現的地方 | AB34: 無 | AC34: 7 | AD34: 妖怪試圖找到當年被背叛並且害夥伴去世的真相並徹底徹底解決禍源的冒險故事 | AE34: 否 | AF34: 是 | AG34: 情感真摯, 諜報野史, 妖怪傳說 | AH34: 會 期待小潔擔任主角 | AI34: 無
A35: 呂存笙 | B35: 生理男 | C35: 21-25 | D35: 台中市 | E35: 中醫系 | F35: 半年一次 | G35: 魔法公主 | H35: 超級英雄片（如：Marvel、DC）, 科幻片, 恐怖片, 動漫片 | I35: 虎姑婆, 好鼻師, 白賊七 | J35: 是 | K35: 虎姑婆 | L35: 白賊七 | M35: 印象中白賊七好像是跟說謊有關(愛耍嘴皮子)，加上他比較生動的台詞，讓人感覺比較貼近，而且比較有在動腦。 | N35: 局長 | O35: 我覺得局長有點可惜，因為他擁有的其實是我最喜歡的能力之一，感覺如果是以自私的角度來看，他感覺也沒有展現出幻覺的極致。如果是我要以封印千年妖怪的道德制高點來看，也感覺力度稍顯不足，會覺得是一個比較沒辦法handle住這能力的角色。 可能是因為我自己稍微有一點刻板印象，在看劇本難免會去跟其他作品的能用幻術系列(相關能力)去做比較。感覺格調上，目的上，手段上，都有點不足。 | P35: 我都理解 | Q35: 蜥蜴 | R35: 局長：幻術 | S35: 單純以後面的劇情看起來，原本是要以封印千年妖怪作為藉口，但好像是可以將自己意識無限傳遞下去達到真正的永生？（自私的角度來看），但我確實有點看不懂核彈的鋪成，只為了局長想要假死嗎 | T35: 場17:頁碼第25頁 | U35: 為什麼要鋪成一個監視核彈的計畫，除了要給局長假死的鋪成之外。 | V35: 看起來沒有覺得太無聊 | W35: 延續前幾題，以核彈的計畫展開，給我的感覺是妖怪跟人已經算可以生活在一起了? 神秘家族應該指的是局長的家族，如果是他封印了妖怪之王，妖怪還會在他底下工作嗎(在他底下的妖怪都沒聽過妖怪之王這一段歷史?)，感覺世界觀好像沒有講得很清楚。 另一個是阿鼻師的女兒被帶走，結果他回說這樣明天他媽媽來接他會找不到人? 這一段話滿齣戲的，不應該是先擔心自己女兒有怎麼樣嗎 | X35: 序6：虎哥將綁著紅繩、色澤溫潤的古代玉佩拿給虎姑婆，並告訴她玉佩是保平安用的護身符 | Y35: 場39：水蛇說：「憑什麼是你，我兒子才是最適合的」 | Z35: 場39：虎姑婆問小潔為什麼幫她，小潔說因為虎姑婆不是壞人，她讀到虎姑婆心聲只是想好好活下去。 | AA35: 覺得不合理，所以會開始懷疑這個護理師有沒有其他安排之類的。 感覺如果真的到那個場地去找病人，也會被開會這幾人嚇到?不應該是這麼稀鬆平常把人帶走。 | AB35: 黑袍糾察隊(雖然不是電影)，平成狸合戰，MARVEL系列超級英雄電影等等 | AC35: 6 | AD35: 妖怪在找活下去的信念 | AE35: 是 | AF35: 否 | AG35: 妖怪傳說 | AH35: 如果有的話，希望可以白賊七當主角 | AI35: 不好意思拖了一些時間，裡面的用詞感覺有點犀利是因為我真的想知道，如果有不懂的話可以跟我用電話討論，你們真的很辛苦！第一次參與這類型的活動有點緊張，謝謝你們！
A36: 李莉穎 | B36: 生理女 | C36: 31-35 | D36: 基隆市 | E36: 教育 | F36: 一週一次或以上 | G36: 人骨聖殿 | H36: 超級英雄片（如：Marvel、DC）, 動作片 (如：007、不可能的任務、玩命關頭), 科幻片, 奇幻冒險片（如：哈利波特系列、魔戒）, 動漫片, 喜劇片 | I36: 虎姑婆, 狐仙 | J36: 否 | K36: 虎姑婆 | L36: 虎姑婆, 白賊七, 好鼻師, 小潔 | M36: 立體 有感情 有個性 | N36: 水男孩 | O36: 純粹的反派 感覺是故事需求而生的角色 | P36: 我都理解 | Q36: 虎姑婆 | R36: 白賊七：詛咒 | S36: 被害者視角 | T36: 虎哥出現的畫面 +好鼻師的能力+北賊七詛咒的能力+把水蛇變成布丁那裡 | U36: 前面起初以為在看小說 閱讀的比較慢 角色之間的關係不太理解 後來就慢慢看懂了 | V36: 無 | W36: 沒有 | X36: 場70：小潔將玉佩還給虎姑婆時，虎姑婆說：「謝謝你。我一直以為，這東西在核爆的時候毀掉了…這是我未婚夫送我的護身符」 | Y36: 場39：水蛇說：「憑什麼是你，我兒子才是最適合的」 | Z36: 場38：虎姑婆在好鼻師暴怒詢問小潔，以及水蛇出現要劫走小潔時，擋在小潔身前保護她。 | AA36: 確實不太合理 但我可以接受 因為劇情安排的關係 | AB36: 怪奇物語 | AC36: 7 | AD36: 妖怪擬人的感情故事 | AE36: 是 | AF36: 是 | AG36: 情感真摯, 諜報野史, 妖怪傳說 | AH36: 都可以 應該是小潔未來的發展 | AI36: 感謝分享 很精彩
A37: 黃楷云 | B37: 生理女 | C37: 15-20 | D37: 台中市 | E37: 高中一年級 | F37: 三個月一次 | G37: 動物方城市2、鏈鋸人蕾潔篇 | H37: 動漫片 | I37: 虎姑婆 | J37: 否 | K37: 虎姑婆 | L37: 虎姑婆 | M37: 對小潔有情有義 | N37: 局長 | O37: 一心為己 | P37: 水蛇、水男孩, 蜥蜴 | Q37: 蜥蜴 | R37: 好鼻師：氣味偵查 | S37: 想延續自己的幻術能力 | T37: 好鼻師使用幻術讓女兒聞到雞蛋糕氣味喚醒女兒 | U37: 無 | V37: 無 | W37: 無 | X37: 場70：小潔將玉佩還給虎姑婆時，虎姑婆說：「謝謝你。我一直以為，這東西在核爆的時候毀掉了…這是我未婚夫送我的護身符」 | Y37: 場56：小潔說：「只要你帶我回去，你兒子就永遠只是接班人的備用品」，水蛇對小潔和虎姑婆說：「我不會讓我兒子的努力白費的」 | Z37: 場43：小潔跟虎姑婆、好鼻師、白賊七三人揭露自己被ELT囚禁、被迫接受訓練的過往，以及她害怕被永遠被困在ELT的恐懼。虎姑婆堅定地告訴小潔，她不會讓小潔被抓回去。 | AA37: 不合理 從劇本裡無從得知鄧小姐安養院與後山基地的相互位置 | AB37: 無 | AC37: 3 | AD37: 眾妖為了解除有人為一己之私所犯下的種種惡行付出努力 | AE37: 否 | AF37: 否 | AG37: 我對這類主題沒有興趣 | AH37: 不期待 | AI37: 無

Sheet 寄送列表
A1: 姓名 | B1: 地址 | C1: 郵遞區號 | D1: 寄送日期（每週四）
A2: {=UNIQUE(#REF!)} -> #NAME? | B2: {=XLOOKUP(A2,#REF!,#REF!)} -> #NAME? | C2: 106 | D2: 46086
A3: #NAME? | B3: {=XLOOKUP(A3,#REF!,#REF!)} -> #NAME? | C3: 324010 | D3: 46086
A4: #NAME? | B4: {=XLOOKUP(A4,#REF!,#REF!)} -> #NAME? | D4: 不用寄送
A5: #NAME? | B5: {=XLOOKUP(A5,#REF!,#REF!)} -> #NAME? | C5: 242065 | D5: 46093
A6: #NAME? | B6: {=XLOOKUP(A6,#REF!,#REF!)} -> #NAME?
A7: #NAME? | B7: {=XLOOKUP(A7,#REF!,#REF!)} -> #NAME?
A8: #NAME? | B8: {=XLOOKUP(A8,#REF!,#REF!)} -> #NAME?
A9: #NAME? | B9: {=XLOOKUP(A9,#REF!,#REF!)} -> #NAME?
A10: #NAME? | B10: {=XLOOKUP(A10,#REF!,#REF!)} -> #NAME?
A11: #NAME? | B11: {=XLOOKUP(A11,#REF!,#REF!)} -> #NAME?
A12: #NAME? | B12: {=XLOOKUP(A12,#REF!,#REF!)} -> #NAME?
A13: #NAME? | B13: {=XLOOKUP(A13,#REF!,#REF!)} -> #NAME?
A14: #NAME? | B14: {=XLOOKUP(A14,#REF!,#REF!)} -> #NAME?
A15: #NAME? | B15: {=XLOOKUP(A15,#REF!,#REF!)} -> #NAME?
A16: #NAME? | B16: {=XLOOKUP(A16,#REF!,#REF!)} -> #NAME?
A17: #NAME? | B17: {=XLOOKUP(A17,#REF!,#REF!)} -> #NAME?
... A39: #NAME? | B39: {=XLOOKUP(A39,#REF!,#REF!)} -> #NAME?
B40: {=XLOOKUP(A40,#REF!,#REF!)} -> #NAME?
B41: {=XLOOKUP(A41,#REF!,#REF!)} -> #NAME?
B42: {=XLOOKUP(A42,#REF!,#REF!)} -> #NAME?
B43: {=XLOOKUP(A43,#REF!,#REF!)} -> #NAME?
B44: {=XLOOKUP(A44,#REF!,#REF!)} -> #NAME?
B45: {=XLOOKUP(A45,#REF!,#REF!)} -> #NAME?
B46: {=XLOOKUP(A46,#REF!,#REF!)} -> #NAME?
B47: {=XLOOKUP(A47,#REF!,#REF!)} -> #NAME?
B48: {=XLOOKUP(A48,#REF!,#REF!)} -> #NAME?
B49: {=XLOOKUP(A49,#REF!,#REF!)} -> #NAME?
B50: {=XLOOKUP(A50,#REF!,#REF!)} -> #NAME?
B51: {=XLOOKUP(A51,#REF!,#REF!)} -> #NAME?
... B1000: {=XLOOKUP(A1000,#REF!,#REF!)} -> #NAME?

Sheet 表單回覆 整合-公式
A1: 姓名 | B1: 性別 | C1: 年齡 | D1: 目前居住縣市 | E1: 工作產業 / 學生請填就讀科系 | F1: 進「電影院」觀影頻率 | G1: 最近進電影院看的電影（數量不限） | H1: 喜歡的電影類型 （多選） | I1: 閱讀劇本前，知道下列哪些妖怪傳說？（可複選） | J1: 閱讀劇本前，是否知道台灣有曾經製作過「核彈」的這段歷史？ | K1: 你認為主角是誰？(單選) | L1: 你喜歡的角色？ (可複選) | M1: 承上題，你喜歡這些角色的原因？ | N1: 你最不喜歡的角色？(單選) | O1: 承上題，你不喜歡這個角色的原因？ | P1: 下列哪個妖怪的超能力對你來說不清楚、看不懂？(可複選) | Q1: 下列哪個妖怪的超能力對你來說，覺得最無聊、最普通？(單選) | R1: 下列哪個妖怪的超能力對你來說，覺得最喜歡、最酷？(單選) | S1: 你覺得「局長」的陰謀是什麼？他為什麼要計劃這個陰謀？ | T1: 閱讀劇本後，你最期待被拍攝出來的場面？或是在文字描繪上有讓你產生強烈的畫面感？ 請提供頁數/場次或具體情節。 | U1: 你是否有看不懂的情節/橋段？ 請說明頁數/場次或具體情節，以及你不理解的部分。 | V1: 劇本哪一段的情節讓你覺得無聊或拖沓？ 請說明頁數/場次或具體情節，以及你覺得拖沓的原因。 | W1: 你是否覺得劇本有哪些地方不合理/出戲的地方？ 請說明頁數/場次或具體情節，以及你覺得不合理/出戲的地方。 | X1: 你在劇本哪一場次，知道虎哥跟虎姑婆是情侶關係？(單選) | Y1: 你在劇本哪一場次，知道水蛇跟水男孩是母子關係？(單選) | Z1: 你覺得覺得小潔跟虎姑婆在哪一場次開始產生革命情感？(單選) | AA1: 在第113場，看到護理師出現在後山基地時，你是否會覺得不合理？ 請回答合理/不合理，並說明原因。 | AB1: 閱讀劇本時，你是否有聯想到其他電影? 請舉例說明 | AC1: 劇本喜愛程度 | AD1: 請用一句話說明，你覺得這個劇本在講述一個什麼故事？ | AE1: 閱讀劇本後，你是否會想進電影院觀看本片？ | AF1: 你是否願意推薦本片給親朋好友？ | AG1: 承上題，你會推薦本片的原因？(可複選) | AH1: 看完劇本後，你會期待這個「變形者宇宙 」的下一部續集或外傳嗎？會期待由哪個角色擔任主角？ | AI1: 你是否還有任何想要補充或分享的想法？
A2: =IFERROR(__xludf.DUMMYFUNCTION("FILTER({'表單回覆 1 (勿動!!!)'!C2:C131, '表單回覆 1 (勿動!!!)'!E2:G131, '表單回覆 1 (勿動!!!)'!I2:I131}, '表單回覆 1 (勿動!!!)'!C2:C131 <> """")"),"杜宥霖") -> 杜宥霖 | B2: =IFERROR(__xludf.DUMMYFUNCTION("""COMPUTED_VALUE"""),"生理男") -> 生理男 | C2: =IFERROR(__xludf.DUMMYFUNCTION("""COMPUTED_VALUE"""),"31-35") -> 31-35 | D2: =IFERROR(__xludf.DUMMYFUNCTION("""COMPUTED_VALUE"""),"臺北市") -> 臺北市 | E2: =IFERROR(__xludf.DUMMYFUNCTION("""COMPUTED_VALUE"""),"研究助理") -> 研究助理 | F2: {=XLOOKUP(A2,'彼此影業 劇本盲測對象調查 - 盲測初選名單 (已自動連結)'!B:B,'彼此影業 劇本盲測對象調查 - 盲測初選名單 (已自動連結)'!H:J)} -> #NAME? | G2: #NAME? | H2: #NAME? | I2: {=XLOOKUP(A2,#REF!,#REF!)} -> #NAME? | J2: #NAME? | K2: #NAME? | L2: #NAME? | M2: #NAME? | N2: #NAME? | O2: #NAME? | P2: #NAME? | Q2: #NAME? | R2: #NAME? | S2: #NAME? | T2: #NAME? | U2: #NAME? | V2: #NAME? | W2: #NAME? | X2: #NAME? | Y2: #NAME? | Z2: #NAME? | AA2: #NAME? | AB2: #NAME? | AC2: #NAME? | AD2: #NAME? | AE2: #NAME? | AF2: #NAME? | AG2: #NAME? | AH2: #NAME? | AI2: #NAME?
A3: =IFERROR(__xludf.DUMMYFUNCTION("""COMPUTED_VALUE"""),"林昭彥") -> 林昭彥 | B3: =IFERROR(__xludf.DUMMYFUNCTION("""COMPUTED_VALUE"""),"生理男") -> 生理男 | C3: =IFERROR(__xludf.DUMMYFUNCTION("""COMPUTED_VALUE"""),"41-45") -> 41-45 | D3: =IFERROR(__xludf.DUMMYFUNCTION("""COMPUTED_VALUE"""),"桃園市") -> 桃園市 | E3: =IFERROR(__xludf.DUMMYFUNCTION("""COMPUTED_VALUE"""),"科技業") -> 科技業 | F3: {=XLOOKUP(A3,'彼此影業 劇本盲測對象調查 - 盲測初選名單 (已自動連結)'!B:B,'彼此影業 劇本盲測對象調查 - 盲測初選名單 (已自動連結)'!H:J)} -> #NAME? | G3: #NAME? | H3: #NAME? | I3: {=XLOOKUP(A3,#REF!,#REF!)} -> #NAME? | J3: #NAME? | K3: #NAME? | L3: #NAME? | M3: #NAME? | N3: #NAME? | O3: #NAME? | P3: #NAME? | Q3: #NAME? | R3: #NAME? | S3: #NAME? | T3: #NAME? | U3: #NAME? | V3: #NAME? | W3: #NAME? | X3: #NAME? | Y3: #NAME? | Z3: #NAME? | AA3: #NAME? | AB3: #NAME? | AC3: #NAME? | AD3: #NAME? | AE3: #NAME? | AF3: #NAME? | AG3: #NAME? | AH3: #NAME? | AI3: #NAME?
A4: =IFERROR(__xludf.DUMMYFUNCTION("""COMPUTED_VALUE"""),"劉瑋澔") -> 劉瑋澔 | B4: =IFERROR(__xludf.DUMMYFUNCTION("""COMPUTED_VALUE"""),"生理男") -> 生理男 | C4: =IFERROR(__xludf.DUMMYFUNCTION("""COMPUTED_VALUE"""),"36-40") -> 36-40 | D4: =IFERROR(__xludf.DUMMYFUNCTION("""COMPUTED_VALUE"""),"臺北市") -> 臺北市 | E4: =IFERROR(__xludf.DUMMYFUNCTION("""COMPUTED_VALUE"""),"網路科技業") -> 網路科技業 | F4: {=XLOOKUP(A4,'彼此影業 劇本盲測對象調查 - 盲測初選名單 (已自動連結)'!B:B,'彼此影業 劇本盲測對象調查 - 盲測初選名單 (已自動連結)'!H:J)} -> #NAME? | G4: #NAME? | H4: #NAME? | I4: {=XLOOKUP(A4,#REF!,#REF!)} -> #NAME? | J4: #NAME? | K4: #NAME? | L4: #NAME? | M4: #NAME? | N4: #NAME? | O4: #NAME? | P4: #NAME? | Q4: #NAME? | R4: #NAME? | S4: #NAME? | T4: #NAME? | U4: #NAME? | V4: #NAME? | W4: #NAME? | X4: #NAME? | Y4: #NAME? | Z4: #NAME? | AA4: #NAME? | AB4: #NAME? | AC4: #NAME? | AD4: #NAME? | AE4: #NAME? | AF4: #NAME? | AG4: #NAME? | AH4: #NAME? | AI4: #NAME?
A5: =IFERROR(__xludf.DUMMYFUNCTION("""COMPUTED_VALUE"""),"林羿豪") -> 林羿豪 | B5: =IFERROR(__xludf.DUMMYFUNCTION("""COMPUTED_VALUE"""),"生理男") -> 生理男 | C5: =IFERROR(__xludf.DUMMYFUNCTION("""COMPUTED_VALUE"""),"36-40") -> 36-40 | D5: =IFERROR(__xludf.DUMMYFUNCTION("""COMPUTED_VALUE"""),"新北市") -> 新北市 | E5: =IFERROR(__xludf.DUMMYFUNCTION("""COMPUTED_VALUE"""),"電商") -> 電商 | F5: {=XLOOKUP(A5,'彼此影業 劇本盲測對象調查 - 盲測初選名單 (已自動連結)'!B:B,'彼此影業 劇本盲測對象調查 - 盲測初選名單 (已自動連結)'!H:J)} -> #NAME? | G5: #NAME? | H5: #NAME? | I5: {=XLOOKUP(A5,#REF!,#REF!)} -> #NAME? | J5: #NAME? | K5: #NAME? | L5: #NAME? | M5: #NAME? | N5: #NAME? | O5: #NAME? | P5: #NAME? | Q5: #NAME? | R5: #NAME? | S5: #NAME? | T5: #NAME? | U5: #NAME? | V5: #NAME? | W5: #NAME? | X5: #NAME? | Y5: #NAME? | Z5: #NAME? | AA5: #NAME? | AB5: #NAME? | AC5: #NAME? | AD5: #NAME? | AE5: #NAME? | AF5: #NAME? | AG5: #NAME? | AH5: #NAME? | AI5: #NAME?
A6: =IFERROR(__xludf.DUMMYFUNCTION("""COMPUTED_VALUE"""),"李艷娟") -> 李艷娟 | B6: =IFERROR(__xludf.DUMMYFUNCTION("""COMPUTED_VALUE"""),"生理女") -> 生理女 | C6: =IFERROR(__xludf.DUMMYFUNCTION("""COMPUTED_VALUE"""),"26-30") -> 26-30 | D6: =IFERROR(__xludf.DUMMYFUNCTION("""COMPUTED_VALUE"""),"新北市") -> 新北市 | E6: =IFERROR(__xludf.DUMMYFUNCTION("""COMPUTED_VALUE"""),"學術研究與教育產業") -> 學術研究與教育產業 | F6: {=XLOOKUP(A6,'彼此影業 劇本盲測對象調查 - 盲測初選名單 (已自動連結)'!B:B,'彼此影業 劇本盲測對象調查 - 盲測初選名單 (已自動連結)'!H:J)} -> #NAME? | G6: #NAME? | H6: #NAME? | I6: {=XLOOKUP(A6,#REF!,#REF!)} -> #NAME? | J6: #NAME? | K6: #NAME? | L6: #NAME? | M6: #NAME? | N6: #NAME? | O6: #NAME? | P6: #NAME? | Q6: #NAME? | R6: #NAME? | S6: #NAME? | T6: #NAME? | U6: #NAME? | V6: #NAME? | W6: #NAME? | X6: #NAME? | Y6: #NAME? | Z6: #NAME? | AA6: #NAME? | AB6: #NAME? | AC6: #NAME? | AD6: #NAME? | AE6: #NAME? | AF6: #NAME? | AG6: #NAME? | AH6: #NAME? | AI6: #NAME?
A7: =IFERROR(__xludf.DUMMYFUNCTION("""COMPUTED_VALUE"""),"吳香穎") -> 吳香穎 | B7: =IFERROR(__xludf.DUMMYFUNCTION("""COMPUTED_VALUE"""),"生理女") -> 生理女 | C7: =IFERROR(__xludf.DUMMYFUNCTION("""COMPUTED_VALUE"""),"31-35") -> 31-35 | D7: =IFERROR(__xludf.DUMMYFUNCTION("""COMPUTED_VALUE"""),"臺北市") -> 臺北市 | E7: =IFERROR(__xludf.DUMMYFUNCTION("""COMPUTED_VALUE"""),"顧問業") -> 顧問業 | F7: {=XLOOKUP(A7,'彼此影業 劇本盲測對象調查 - 盲測初選名單 (已自動連結)'!B:B,'彼此影業 劇本盲測對象調查 - 盲測初選名單 (已自動連結)'!H:J)} -> #NAME? | G7: #NAME? | H7: #NAME? | I7: {=XLOOKUP(A7,#REF!,#REF!)} -> #NAME? | J7: #NAME? | K7: #NAME? | L7: #NAME? | M7: #NAME? | N7: #NAME? | O7: #NAME? | P7: #NAME? | Q7: #NAME? | R7: #NAME? | S7: #NAME? | T7: #NAME? | U7: #NAME? | V7: #NAME? | W7: #NAME? | X7: #NAME? | Y7: #NAME? | Z7: #NAME? | AA7: #NAME? | AB7: #NAME? | AC7: #NAME? | AD7: #NAME? | AE7: #NAME? | AF7: #NAME? | AG7: #NAME? | AH7: #NAME? | AI7: #NAME?
A8: =IFERROR(__xludf.DUMMYFUNCTION("""COMPUTED_VALUE"""),"阮奕安") -> 阮奕安 | B8: =IFERROR(__xludf.DUMMYFUNCTION("""COMPUTED_VALUE"""),"生理男") -> 生理男 | C8: =IFERROR(__xludf.DUMMYFUNCTION("""COMPUTED_VALUE"""),"26-30") -> 26-30 | D8: =IFERROR(__xludf.DUMMYFUNCTION("""COMPUTED_VALUE"""),"桃園市") -> 桃園市 | E8: =IFERROR(__xludf.DUMMYFUNCTION("""COMPUTED_VALUE"""),"電商") -> 電商 | F8: {=XLOOKUP(A8,'彼此影業 劇本盲測對象調查 - 盲測初選名單 (已自動連結)'!B:B,'彼此影業 劇本盲測對象調查 - 盲測初選名單 (已自動連結)'!H:J)} -> #NAME? | G8: #NAME? | H8: #NAME? | I8: {=XLOOKUP(A8,#REF!,#REF!)} -> #NAME? | J8: #NAME? | K8: #NAME? | L8: #NAME? | M8: #NAME? | N8: #NAME? | O8: #NAME? | P8: #NAME? | Q8: #NAME? | R8: #NAME? | S8: #NAME? | T8: #NAME? | U8: #NAME? | V8: #NAME? | W8: #NAME? | X8: #NAME? | Y8: #NAME? | Z8: #NAME? | AA8: #NAME? | AB8: #NAME? | AC8: #NAME? | AD8: #NAME? | AE8: #NAME? | AF8: #NAME? | AG8: #NAME? | AH8: #NAME? | AI8: #NAME?
A9: =IFERROR(__xludf.DUMMYFUNCTION("""COMPUTED_VALUE"""),"謝佩珊") -> 謝佩珊 | B9: =IFERROR(__xludf.DUMMYFUNCTION("""COMPUTED_VALUE"""),"生理女") -> 生理女 | C9: =IFERROR(__xludf.DUMMYFUNCTION("""COMPUTED_VALUE"""),"31-35") -> 31-35 | D9: =IFERROR(__xludf.DUMMYFUNCTION("""COMPUTED_VALUE"""),"新北市") -> 新北市 | E9: =IFERROR(__xludf.DUMMYFUNCTION("""COMPUTED_VALUE"""),"數位行銷") -> 數位行銷 | F9: {=XLOOKUP(A9,'彼此影業 劇本盲測對象調查 - 盲測初選名單 (已自動連結)'!B:B,'彼此影業 劇本盲測對象調查 - 盲測初選名單 (已自動連結)'!H:J)} -> #NAME? | G9: #NAME? | H9: #NAME? | I9: {=XLOOKUP(A9,#REF!,#REF!)} -> #NAME? | J9: #NAME? | K9: #NAME? | L9: #NAME? | M9: #NAME? | N9: #NAME? | O9: #NAME? | P9: #NAME? | Q9: #NAME? | R9: #NAME? | S9: #NAME? | T9: #NAME? | U9: #NAME? | V9: #NAME? | W9: #NAME? | X9: #NAME? | Y9: #NAME? | Z9: #NAME? | AA9: #NAME? | AB9: #NAME? | AC9: #NAME? | AD9: #NAME? | AE9: #NAME? | AF9: #NAME? | AG9: #NAME? | AH9: #NAME? | AI9: #NAME?
A10: =IFERROR(__xludf.DUMMYFUNCTION("""COMPUTED_VALUE"""),"許若莉") -> 許若莉 | B10: =IFERROR(__xludf.DUMMYFUNCTION("""COMPUTED_VALUE"""),"生理女") -> 生理女 | C10: =IFERROR(__xludf.DUMMYFUNCTION("""COMPUTED_VALUE"""),"26-30") -> 26-30 | D10: =IFERROR(__xludf.DUMMYFUNCTION("""COMPUTED_VALUE"""),"新北市") -> 新北市 | E10: =IFERROR(__xludf.DUMMYFUNCTION("""COMPUTED_VALUE"""),"餐飲業") -> 餐飲業 | F10: {=XLOOKUP(A10,'彼此影業 劇本盲測對象調查 - 盲測初選名單 (已自動連結)'!B:B,'彼此影業 劇本盲測對象調查 - 盲測初選名單 (已自動連結)'!H:J)} -> #NAME? | G10: #NAME? | H10: #NAME? | I10: {=XLOOKUP(A10,#REF!,#REF!)} -> #NAME? | J10: #NAME? | K10: #NAME? | L10: #NAME? | M10: #NAME? | N10: #NAME? | O10: #NAME? | P10: #NAME? | Q10: #NAME? | R10: #NAME? | S10: #NAME? | T10: #NAME? | U10: #NAME? | V10: #NAME? | W10: #NAME? | X10: #NAME? | Y10: #NAME? | Z10: #NAME? | AA10: #NAME? | AB10: #NAME? | AC10: #NAME? | AD10: #NAME? | AE10: #NAME? | AF10: #NAME? | AG10: #NAME? | AH10: #NAME? | AI10: #NAME?
A11: =IFERROR(__xludf.DUMMYFUNCTION("""COMPUTED_VALUE"""),"林哲毅") -> 林哲毅 | B11: =IFERROR(__xludf.DUMMYFUNCTION("""COMPUTED_VALUE"""),"生理男") -> 生理男 | C11: =IFERROR(__xludf.DUMMYFUNCTION("""COMPUTED_VALUE"""),"26-30") -> 26-30 | D11: =IFERROR(__xludf.DUMMYFUNCTION("""COMPUTED_VALUE"""),"臺北市") -> 臺北市 | E11: =IFERROR(__xludf.DUMMYFUNCTION("""COMPUTED_VALUE"""),"醫療業") -> 醫療業 | F11: {=XLOOKUP(A11,'彼此影業 劇本盲測對象調查 - 盲測初選名單 (已自動連結)'!B:B,'彼此影業 劇本盲測對象調查 - 盲測初選名單 (已自動連結)'!H:J)} -> #NAME? | G11: #NAME? | H11: #NAME? | I11: {=XLOOKUP(A11,#REF!,#REF!)} -> #NAME? | J11: #NAME? | K11: #NAME? | L11: #NAME? | M11: #NAME? | N11: #NAME? | O11: #NAME? | P11: #NAME? | Q11: #NAME? | R11: #NAME? | S11: #NAME? | T11: #NAME? | U11: #NAME? | V11: #NAME? | W11: #NAME? | X11: #NAME? | Y11: #NAME? | Z11: #NAME? | AA11: #NAME? | AB11: #NAME? | AC11: #NAME? | AD11: #NAME? | AE11: #NAME? | AF11: #NAME? | AG11: #NAME? | AH11: #NAME? | AI11: #NAME?
A12: =IFERROR(__xludf.DUMMYFUNCTION("""COMPUTED_VALUE"""),"許偉康") -> 許偉康 | B12: =IFERROR(__xludf.DUMMYFUNCTION("""COMPUTED_VALUE"""),"生理男") -> 生理男 | C12: =IFERROR(__xludf.DUMMYFUNCTION("""COMPUTED_VALUE"""),"36-40") -> 36-40 | D12: =IFERROR(__xludf.DUMMYFUNCTION("""COMPUTED_VALUE"""),"桃園市") -> 桃園市 | E12: =IFERROR(__xludf.DUMMYFUNCTION("""COMPUTED_VALUE"""),"工程師") -> 工程師 | F12: {=XLOOKUP(A12,'彼此影業 劇本盲測對象調查 - 盲測初選名單 (已自動連結)'!B:B,'彼此影業 劇本盲測對象調查 - 盲測初選名單 (已自動連結)'!H:J)} -> #NAME? | G12: #NAME? | H12: #NAME? | I12: {=XLOOKUP(A12,#REF!,#REF!)} -> #NAME? | J12: #NAME? | K12: #NAME? | L12: #NAME? | M12: #NAME? | N12: #NAME? | O12: #NAME? | P12: #NAME? | Q12: #NAME? | R12: #NAME? | S12: #NAME? | T12: #NAME? | U12: #NAME? | V12: #NAME? | W12: #NAME? | X12: #NAME? | Y12: #NAME? | Z12: #NAME? | AA12: #NAME? | AB12: #NAME? | AC12: #NAME? | AD12: #NAME? | AE12: #NAME? | AF12: #NAME? | AG12: #NAME? | AH12: #NAME? | AI12: #NAME?
A13: =IFERROR(__xludf.DUMMYFUNCTION("""COMPUTED_VALUE"""),"謝麗菁") -> 謝麗菁 | B13: =IFERROR(__xludf.DUMMYFUNCTION("""COMPUTED_VALUE"""),"生理女") -> 生理女 | C13: =IFERROR(__xludf.DUMMYFUNCTION("""COMPUTED_VALUE"""),"41-45") -> 41-45 | D13: =IFERROR(__xludf.DUMMYFUNCTION("""COMPUTED_VALUE"""),"新北市") -> 新北市 | E13: =IFERROR(__xludf.DUMMYFUNCTION("""COMPUTED_VALUE"""),"自由接案（娛樂唱片）") -> 自由接案（娛樂唱片） | F13: {=XLOOKUP(A13,'彼此影業 劇本盲測對象調查 - 盲測初選名單 (已自動連結)'!B:B,'彼此影業 劇本盲測對象調查 - 盲測初選名單 (已自動連結)'!H:J)} -> #NAME? | G13: #NAME? | H13: #NAME? | I13: {=XLOOKUP(A13,#REF!,#REF!)} -> #NAME? | J13: #NAME? | K13: #NAME? | L13: #NAME? | M13: #NAME? | N13: #NAME? | O13: #NAME? | P13: #NAME? | Q13: #NAME? | R13: #NAME? | S13: #NAME? | T13: #NAME? | U13: #NAME? | V13: #NAME? | W13: #NAME? | X13: #NAME? | Y13: #NAME? | Z13: #NAME? | AA13: #NAME? | AB13: #NAME? | AC13: #NAME? | AD13: #NAME? | AE13: #NAME? | AF13: #NAME? | AG13: #NAME? | AH13: #NAME? | AI13: #NAME?
A14: =IFERROR(__xludf.DUMMYFUNCTION("""COMPUTED_VALUE"""),"原詩涵") -> 原詩涵 | B14: =IFERROR(__xludf.DUMMYFUNCTION("""COMPUTED_VALUE"""),"生理女") -> 生理女 | C14: =IFERROR(__xludf.DUMMYFUNCTION("""COMPUTED_VALUE"""),"31-35") -> 31-35 | D14: =IFERROR(__xludf.DUMMYFUNCTION("""COMPUTED_VALUE"""),"桃園市") -> 桃園市 | E14: =IFERROR(__xludf.DUMMYFUNCTION("""COMPUTED_VALUE"""),"線上課程、數位內容產業") -> 線上課程、數位內容產業 | F14: {=XLOOKUP(A14,'彼此影業 劇本盲測對象調查 - 盲測初選名單 (已自動連結)'!B:B,'彼此影業 劇本盲測對象調查 - 盲測初選名單 (已自動連結)'!H:J)} -> #NAME? | G14: #NAME? | H14: #NAME? | I14: {=XLOOKUP(A14,#REF!,#REF!)} -> #NAME? | J14: #NAME? | K14: #NAME? | L14: #NAME? | M14: #NAME? | N14: #NAME? | O14: #NAME? | P14: #NAME? | Q14: #NAME? | R14: #NAME? | S14: #NAME? | T14: #NAME? | U14: #NAME? | V14: #NAME? | W14: #NAME? | X14: #NAME? | Y14: #NAME? | Z14: #NAME? | AA14: #NAME? | AB14: #NAME? | AC14: #NAME? | AD14: #NAME? | AE14: #NAME? | AF14: #NAME? | AG14: #NAME? | AH14: #NAME? | AI14: #NAME?
A15: =IFERROR(__xludf.DUMMYFUNCTION("""COMPUTED_VALUE"""),"王羿涵") -> 王羿涵 | B15: =IFERROR(__xludf.DUMMYFUNCTION("""COMPUTED_VALUE"""),"生理女") -> 生理女 | C15: =IFERROR(__xludf.DUMMYFUNCTION("""COMPUTED_VALUE"""),"26-30") -> 26-30 | D15: =IFERROR(__xludf.DUMMYFUNCTION("""COMPUTED_VALUE"""),"臺北市") -> 臺北市 | E15: =IFERROR(__xludf.DUMMYFUNCTION("""COMPUTED_VALUE"""),"法律服務業") -> 法律服務業 | F15: {=XLOOKUP(A15,'彼此影業 劇本盲測對象調查 - 盲測初選名單 (已自動連結)'!B:B,'彼此影業 劇本盲測對象調查 - 盲測初選名單 (已自動連結)'!H:J)} -> #NAME? | G15: #NAME? | H15: #NAME? | I15: {=XLOOKUP(A15,#REF!,#REF!)} -> #NAME? | J15: #NAME? | K15: #NAME? | L15: #NAME? | M15: #NAME? | N15: #NAME? | O15: #NAME? | P15: #NAME? | Q15: #NAME? | R15: #NAME? | S15: #NAME? | T15: #NAME? | U15: #NAME? | V15: #NAME? | W15: #NAME? | X15: #NAME? | Y15: #NAME? | Z15: #NAME? | AA15: #NAME? | AB15: #NAME? | AC15: #NAME? | AD15: #NAME? | AE15: #NAME? | AF15: #NAME? | AG15: #NAME? | AH15: #NAME? | AI15: #NAME?
A16: =IFERROR(__xludf.DUMMYFUNCTION("""COMPUTED_VALUE"""),"林冠邦") -> 林冠邦 | B16: =IFERROR(__xludf.DUMMYFUNCTION("""COMPUTED_VALUE"""),"生理男") -> 生理男 | C16: =IFERROR(__xludf.DUMMYFUNCTION("""COMPUTED_VALUE"""),"41-45") -> 41-45 | D16: =IFERROR(__xludf.DUMMYFUNCTION("""COMPUTED_VALUE"""),"臺北市") -> 臺北市 | E16: =IFERROR(__xludf.DUMMYFUNCTION("""COMPUTED_VALUE"""),"國際貿易+餐廚用品設計製造業 / 國際企業系+機械系") -> 國際貿易+餐廚用品設計製造業 / 國際企業系+機械系 | F16: {=XLOOKUP(A16,'彼此影業 劇本盲測對象調查 - 盲測初選名單 (已自動連結)'!B:B,'彼此影業 劇本盲測對象調查 - 盲測初選名單 (已自動連結)'!H:J)} -> #NAME? | G16: #NAME? | H16: #NAME? | I16: {=XLOOKUP(A16,#REF!,#REF!)} -> #NAME? | J16: #NAME? | K16: #NAME? | L16: #NAME? | M16: #NAME? | N16: #NAME? | O16: #NAME? | P16: #NAME? | Q16: #NAME? | R16: #NAME? | S16: #NAME? | T16: #NAME? | U16: #NAME? | V16: #NAME? | W16: #NAME? | X16: #NAME? | Y16: #NAME? | Z16: #NAME? | AA16: #NAME? | AB16: #NAME? | AC16: #NAME? | AD16: #NAME? | AE16: #NAME? | AF16: #NAME? | AG16: #NAME? | AH16: #NAME? | AI16: #NAME?
A17: =IFERROR(__xludf.DUMMYFUNCTION("""COMPUTED_VALUE"""),"徐仁恩") -> 徐仁恩 | B17: =IFERROR(__xludf.DUMMYFUNCTION("""COMPUTED_VALUE"""),"生理男") -> 生理男 | C17: =IFERROR(__xludf.DUMMYFUNCTION("""COMPUTED_VALUE"""),"41-45") -> 41-45 | D17: =IFERROR(__xludf.DUMMYFUNCTION("""COMPUTED_VALUE"""),"臺北市") -> 臺北市 | E17: =IFERROR(__xludf.DUMMYFUNCTION("""COMPUTED_VALUE"""),"營造業") -> 營造業 | F17: {=XLOOKUP(A17,'彼此影業 劇本盲測對象調查 - 盲測初選名單 (已自動連結)'!B:B,'彼此影業 劇本盲測對象調查 - 盲測初選名單 (已自動連結)'!H:J)} -> #NAME? | G17: #NAME? | H17: #NAME? | I17: {=XLOOKUP(A17,#REF!,#REF!)} -> #NAME? | J17: #NAME? | K17: #NAME? | L17: #NAME? | M17: #NAME? | N17: #NAME? | O17: #NAME? | P17: #NAME? | Q17: #NAME? | R17: #NAME? | S17: #NAME? | T17: #NAME? | U17: #NAME? | V17: #NAME? | W17: #NAME? | X17: #NAME? | Y17: #NAME? | Z17: #NAME? | AA17: #NAME? | AB17: #NAME? | AC17: #NAME? | AD17: #NAME? | AE17: #NAME? | AF17: #NAME? | AG17: #NAME? | AH17: #NAME? | AI17: #NAME?
A18: =IFERROR(__xludf.DUMMYFUNCTION("""COMPUTED_VALUE"""),"莊字東") -> 莊字東 | B18: =IFERROR(__xludf.DUMMYFUNCTION("""COMPUTED_VALUE"""),"生理男") -> 生理男 | C18: =IFERROR(__xludf.DUMMYFUNCTION("""COMPUTED_VALUE"""),"21-25") -> 21-25 | D18: =IFERROR(__xludf.DUMMYFUNCTION("""COMPUTED_VALUE"""),"新北市") -> 新北市 | E18: =IFERROR(__xludf.DUMMYFUNCTION("""COMPUTED_VALUE"""),"哲學系") -> 哲學系 | F18: {=XLOOKUP(A18,'彼此影業 劇本盲測對象調查 - 盲測初選名單 (已自動連結)'!B:B,'彼此影業 劇本盲測對象調查 - 盲測初選名單 (已自動連結)'!H:J)} -> #NAME? | G18: #NAME? | H18: #NAME? | I18: {=XLOOKUP(A18,#REF!,#REF!)} -> #NAME? | J18: #NAME? | K18: #NAME? | L18: #NAME? | M18: #NAME? | N18: #NAME? | O18: #NAME? | P18: #NAME? | Q18: #NAME? | R18: #NAME? | S18: #NAME? | T18: #NAME? | U18: #NAME? | V18: #NAME? | W18: #NAME? | X18: #NAME? | Y18: #NAME? | Z18: #NAME? | AA18: #NAME? | AB18: #NAME? | AC18: #NAME? | AD18: #NAME? | AE18: #NAME? | AF18: #NAME? | AG18: #NAME? | AH18: #NAME? | AI18: #NAME?
A19: =IFERROR(__xludf.DUMMYFUNCTION("""COMPUTED_VALUE"""),"李守治") -> 李守治 | B19: =IFERROR(__xludf.DUMMYFUNCTION("""COMPUTED_VALUE"""),"生理男") -> 生理男 | C19: =IFERROR(__xludf.DUMMYFUNCTION("""COMPUTED_VALUE"""),"26-30") -> 26-30 | D19: =IFERROR(__xludf.DUMMYFUNCTION("""COMPUTED_VALUE"""),"新北市") -> 新北市 | E19: =IFERROR(__xludf.DUMMYFUNCTION("""COMPUTED_VALUE"""),"集資／線上課程") -> 集資／線上課程 | F19: {=XLOOKUP(A19,'彼此影業 劇本盲測對象調查 - 盲測初選名單 (已自動連結)'!B:B,'彼此影業 劇本盲測對象調查 - 盲測初選名單 (已自動連結)'!H:J)} -> #NAME? | G19: #NAME? | H19: #NAME? | I19: {=XLOOKUP(A19,#REF!,#REF!)} -> #NAME? | J19: #NAME? | K19: #NAME? | L19: #NAME? | M19: #NAME? | N19: #NAME? | O19: #NAME? | P19: #NAME? | Q19: #NAME? | R19: #NAME? | S19: #NAME? | T19: #NAME? | U19: #NAME? | V19: #NAME? | W19: #NAME? | X19: #NAME? | Y19: #NAME? | Z19: #NAME? | AA19: #NAME? | AB19: #NAME? | AC19: #NAME? | AD19: #NAME? | AE19: #NAME? | AF19: #NAME? | AG19: #NAME? | AH19: #NAME? | AI19: #NAME?
A20: =IFERROR(__xludf.DUMMYFUNCTION("""COMPUTED_VALUE"""),"吳幼雯") -> 吳幼雯 | B20: =IFERROR(__xludf.DUMMYFUNCTION("""COMPUTED_VALUE"""),"生理女") -> 生理女 | C20: =IFERROR(__xludf.DUMMYFUNCTION("""COMPUTED_VALUE"""),"46-50") -> 46-50 | D20: =IFERROR(__xludf.DUMMYFUNCTION("""COMPUTED_VALUE"""),"新北市") -> 新北市 | E20: =IFERROR(__xludf.DUMMYFUNCTION("""COMPUTED_VALUE"""),"手工藝工作室") -> 手工藝工作室 | F20: {=XLOOKUP(A20,'彼此影業 劇本盲測對象調查 - 盲測初選名單 (已自動連結)'!B:B,'彼此影業 劇本盲測對象調查 - 盲測初選名單 (已自動連結)'!H:J)} -> #NAME? | G20: #NAME? | H20: #NAME? | I20: {=XLOOKUP(A20,#REF!,#REF!)} -> #NAME? | J20: #NAME? | K20: #NAME? | L20: #NAME? | M20: #NAME? | N20: #NAME? | O20: #NAME? | P20: #NAME? | Q20: #NAME? | R20: #NAME? | S20: #NAME? | T20: #NAME? | U20: #NAME? | V20: #NAME? | W20: #NAME? | X20: #NAME? | Y20: #NAME? | Z20: #NAME? | AA20: #NAME? | AB20: #NAME? | AC20: #NAME? | AD20: #NAME? | AE20: #NAME? | AF20: #NAME? | AG20: #NAME? | AH20: #NAME? | AI20: #NAME?
A21: =IFERROR(__xludf.DUMMYFUNCTION("""COMPUTED_VALUE"""),"許若亮") -> 許若亮 | B21: =IFERROR(__xludf.DUMMYFUNCTION("""COMPUTED_VALUE"""),"生理女") -> 生理女 | C21: =IFERROR(__xludf.DUMMYFUNCTION("""COMPUTED_VALUE"""),"26-30") -> 26-30 | D21: =IFERROR(__xludf.DUMMYFUNCTION("""COMPUTED_VALUE"""),"新北市") -> 新北市 | E21: =IFERROR(__xludf.DUMMYFUNCTION("""COMPUTED_VALUE"""),"金融業") -> 金融業 | F21: {=XLOOKUP(A21,'彼此影業 劇本盲測對象調查 - 盲測初選名單 (已自動連結)'!B:B,'彼此影業 劇本盲測對象調查 - 盲測初選名單 (已自動連結)'!H:J)} -> #NAME? | G21: #NAME? | H21: #NAME? | I21: {=XLOOKUP(A21,#REF!,#REF!)} -> #NAME? | J21: #NAME? | K21: #NAME? | L21: #NAME? | M21: #NAME? | N21: #NAME? | O21: #NAME? | P21: #NAME? | Q21: #NAME? | R21: #NAME? | S21: #NAME? | T21: #NAME? | U21: #NAME? | V21: #NAME? | W21: #NAME? | X21: #NAME? | Y21: #NAME? | Z21: #NAME? | AA21: #NAME? | AB21: #NAME? | AC21: #NAME? | AD21: #NAME? | AE21: #NAME? | AF21: #NAME? | AG21: #NAME? | AH21: #NAME? | AI21: #NAME?
A22: =IFERROR(__xludf.DUMMYFUNCTION("""COMPUTED_VALUE"""),"廖元維") -> 廖元維 | B22: =IFERROR(__xludf.DUMMYFUNCTION("""COMPUTED_VALUE"""),"生理男") -> 生理男 | C22: =IFERROR(__xludf.DUMMYFUNCTION("""COMPUTED_VALUE"""),"21-25") -> 21-25 | D22: =IFERROR(__xludf.DUMMYFUNCTION("""COMPUTED_VALUE"""),"桃園市") -> 桃園市 | E22: =IFERROR(__xludf.DUMMYFUNCTION("""COMPUTED_VALUE"""),"資訊工程系") -> 資訊工程系 | F22: {=XLOOKUP(A22,'彼此影業 劇本盲測對象調查 - 盲測初選名單 (已自動連結)'!B:B,'彼此影業 劇本盲測對象調查 - 盲測初選名單 (已自動連結)'!H:J)} -> #NAME? | G22: #NAME? | H22: #NAME? | I22: {=XLOOKUP(A22,#REF!,#REF!)} -> #NAME? | J22: #NAME? | K22: #NAME? | L22: #NAME? | M22: #NAME? | N22: #NAME? | O22: #NAME? | P22: #NAME? | Q22: #NAME? | R22: #NAME? | S22: #NAME? | T22: #NAME? | U22: #NAME? | V22: #NAME? | W22: #NAME? | X22: #NAME? | Y22: #NAME? | Z22: #NAME? | AA22: #NAME? | AB22: #NAME? | AC22: #NAME? | AD22: #NAME? | AE22: #NAME? | AF22: #NAME? | AG22: #NAME? | AH22: #NAME? | AI22: #NAME?
A23: =IFERROR(__xludf.DUMMYFUNCTION("""COMPUTED_VALUE"""),"趙珩宇") -> 趙珩宇 | B23: =IFERROR(__xludf.DUMMYFUNCTION("""COMPUTED_VALUE"""),"生理男") -> 生理男 | C23: =IFERROR(__xludf.DUMMYFUNCTION("""COMPUTED_VALUE"""),"31-35") -> 31-35 | D23: =IFERROR(__xludf.DUMMYFUNCTION("""COMPUTED_VALUE"""),"臺北市") -> 臺北市 | E23: =IFERROR(__xludf.DUMMYFUNCTION("""COMPUTED_VALUE"""),"教師") -> 教師 | F23: {=XLOOKUP(A23,'彼此影業 劇本盲測對象調查 - 盲測初選名單 (已自動連結)'!B:B,'彼此影業 劇本盲測對象調查 - 盲測初選名單 (已自動連結)'!H:J)} -> #NAME? | G23: #NAME? | H23: #NAME? | I23: {=XLOOKUP(A23,#REF!,#REF!)} -> #NAME? | J23: #NAME? | K23: #NAME? | L23: #NAME? | M23: #NAME? | N23: #NAME? | O23: #NAME? | P23: #NAME? | Q23: #NAME? | R23: #NAME? | S23: #NAME? | T23: #NAME? | U23: #NAME? | V23: #NAME? | W23: #NAME? | X23: #NAME? | Y23: #NAME? | Z23: #NAME? | AA23: #NAME? | AB23: #NAME? | AC23: #NAME? | AD23: #NAME? | AE23: #NAME? | AF23: #NAME? | AG23: #NAME? | AH23: #NAME? | AI23: #NAME?
A24: =IFERROR(__xludf.DUMMYFUNCTION("""COMPUTED_VALUE"""),"盧晉德") -> 盧晉德 | B24: =IFERROR(__xludf.DUMMYFUNCTION("""COMPUTED_VALUE"""),"生理男") -> 生理男 | C24: =IFERROR(__xludf.DUMMYFUNCTION("""COMPUTED_VALUE"""),"26-30") -> 26-30 | D24: =IFERROR(__xludf.DUMMYFUNCTION("""COMPUTED_VALUE"""),"新北市") -> 新北市 | E24: =IFERROR(__xludf.DUMMYFUNCTION("""COMPUTED_VALUE"""),"生技") -> 生技 | F24: {=XLOOKUP(A24,'彼此影業 劇本盲測對象調查 - 盲測初選名單 (已自動連結)'!B:B,'彼此影業 劇本盲測對象調查 - 盲測初選名單 (已自動連結)'!H:J)} -> #NAME? | G24: #NAME? | H24: #NAME? | I24: {=XLOOKUP(A24,#REF!,#REF!)} -> #NAME? | J24: #NAME? | K24: #NAME? | L24: #NAME? | M24: #NAME? | N24: #NAME? | O24: #NAME? | P24: #NAME? | Q24: #NAME? | R24: #NAME? | S24: #NAME? | T24: #NAME? | U24: #NAME? | V24: #NAME? | W24: #NAME? | X24: #NAME? | Y24: #NAME? | Z24: #NAME? | AA24: #NAME? | AB24: #NAME? | AC24: #NAME? | AD24: #NAME? | AE24: #NAME? | AF24: #NAME? | AG24: #NAME? | AH24: #NAME? | AI24: #NAME?
A25: =IFERROR(__xludf.DUMMYFUNCTION("""COMPUTED_VALUE"""),"陳亮妤") -> 陳亮妤 | B25: =IFERROR(__xludf.DUMMYFUNCTION("""COMPUTED_VALUE"""),"生理女") -> 生理女 | C25: =IFERROR(__xludf.DUMMYFUNCTION("""COMPUTED_VALUE"""),"26-30") -> 26-30 | D25: =IFERROR(__xludf.DUMMYFUNCTION("""COMPUTED_VALUE"""),"泰山") -> 泰山 | E25: =IFERROR(__xludf.DUMMYFUNCTION("""COMPUTED_VALUE"""),"政府機關") -> 政府機關 | F25: {=XLOOKUP(A25,'彼此影業 劇本盲測對象調查 - 盲測初選名單 (已自動連結)'!B:B,'彼此影業 劇本盲測對象調查 - 盲測初選名單 (已自動連結)'!H:J)} -> #NAME? | G25: #NAME? | H25: #NAME? | I25: {=XLOOKUP(A25,#REF!,#REF!)} -> #NAME? | J25: #NAME? | K25: #NAME? | L25: #NAME? | M25: #NAME? | N25: #NAME? | O25: #NAME? | P25: #NAME? | Q25: #NAME? | R25: #NAME? | S25: #NAME? | T25: #NAME? | U25: #NAME? | V25: #NAME? | W25: #NAME? | X25: #NAME? | Y25: #NAME? | Z25: #NAME? | AA25: #NAME? | AB25: #NAME? | AC25: #NAME? | AD25: #NAME? | AE25: #NAME? | AF25: #NAME? | AG25: #NAME? | AH25: #NAME? | AI25: #NAME?
A26: =IFERROR(__xludf.DUMMYFUNCTION("""COMPUTED_VALUE"""),"施相宇") -> 施相宇 | B26: =IFERROR(__xludf.DUMMYFUNCTION("""COMPUTED_VALUE"""),"生理男") -> 生理男 | C26: =IFERROR(__xludf.DUMMYFUNCTION("""COMPUTED_VALUE"""),"26-30") -> 26-30 | D26: =IFERROR(__xludf.DUMMYFUNCTION("""COMPUTED_VALUE"""),"新北市") -> 新北市 | E26: =IFERROR(__xludf.DUMMYFUNCTION("""COMPUTED_VALUE"""),"建築/營造") -> 建築/營造 | F26: {=XLOOKUP(A26,'彼此影業 劇本盲測對象調查 - 盲測初選名單 (已自動連結)'!B:B,'彼此影業 劇本盲測對象調查 - 盲測初選名單 (已自動連結)'!H:J)} -> #NAME? | G26: #NAME? | H26: #NAME? | I26: {=XLOOKUP(A26,#REF!,#REF!)} -> #NAME? | J26: #NAME? | K26: #NAME? | L26: #NAME? | M26: #NAME? | N26: #NAME? | O26: #NAME? | P26: #NAME? | Q26: #NAME? | R26: #NAME? | S26: #NAME? | T26: #NAME? | U26: #NAME? | V26: #NAME? | W26: #NAME? | X26: #NAME? | Y26: #NAME? | Z26: #NAME? | AA26: #NAME? | AB26: #NAME? | AC26: #NAME? | AD26: #NAME? | AE26: #NAME? | AF26: #NAME? | AG26: #NAME? | AH26: #NAME? | AI26: #NAME?
A27: =IFERROR(__xludf.DUMMYFUNCTION("""COMPUTED_VALUE"""),"張旭華") -> 張旭華 | B27: =IFERROR(__xludf.DUMMYFUNCTION("""COMPUTED_VALUE"""),"生理女") -> 生理女 | C27: =IFERROR(__xludf.DUMMYFUNCTION("""COMPUTED_VALUE"""),"21-25") -> 21-25 | D27: =IFERROR(__xludf.DUMMYFUNCTION("""COMPUTED_VALUE"""),"臺北") -> 臺北 | E27: =IFERROR(__xludf.DUMMYFUNCTION("""COMPUTED_VALUE"""),"金融業") -> 金融業 | F27: {=XLOOKUP(A27,'彼此影業 劇本盲測對象調查 - 盲測初選名單 (已自動連結)'!B:B,'彼此影業 劇本盲測對象調查 - 盲測初選名單 (已自動連結)'!H:J)} -> #NAME? | G27: #NAME? | H27: #NAME? | I27: {=XLOOKUP(A27,#REF!,#REF!)} -> #NAME? | J27: #NAME? | K27: #NAME? | L27: #NAME? | M27: #NAME? | N27: #NAME? | O27: #NAME? | P27: #NAME? | Q27: #NAME? | R27: #NAME? | S27: #NAME? | T27: #NAME? | U27: #NAME? | V27: #NAME? | W27: #NAME? | X27: #NAME? | Y27: #NAME? | Z27: #NAME? | AA27: #NAME? | AB27: #NAME? | AC27: #NAME? | AD27: #NAME? | AE27: #NAME? | AF27: #NAME? | AG27: #NAME? | AH27: #NAME? | AI27: #NAME?
A28: =IFERROR(__xludf.DUMMYFUNCTION("""COMPUTED_VALUE"""),"許哲維") -> 許哲維 | B28: =IFERROR(__xludf.DUMMYFUNCTION("""COMPUTED_VALUE"""),"生理男") -> 生理男 | C28: =IFERROR(__xludf.DUMMYFUNCTION("""COMPUTED_VALUE"""),"36-40") -> 36-40 | D28: =IFERROR(__xludf.DUMMYFUNCTION("""COMPUTED_VALUE"""),"新北市") -> 新北市 | E28: =IFERROR(__xludf.DUMMYFUNCTION("""COMPUTED_VALUE"""),"金融業") -> 金融業 | F28: {=XLOOKUP(A28,'彼此影業 劇本盲測對象調查 - 盲測初選名單 (已自動連結)'!B:B,'彼此影業 劇本盲測對象調查 - 盲測初選名單 (已自動連結)'!H:J)} -> #NAME? | G28: #NAME? | H28: #NAME? | I28: {=XLOOKUP(A28,#REF!,#REF!)} -> #NAME? | J28: #NAME? | K28: #NAME? | L28: #NAME? | M28: #NAME? | N28: #NAME? | O28: #NAME? | P28: #NAME? | Q28: #NAME? | R28: #NAME? | S28: #NAME? | T28: #NAME? | U28: #NAME? | V28: #NAME? | W28: #NAME? | X28: #NAME? | Y28: #NAME? | Z28: #NAME? | AA28: #NAME? | AB28: #NAME? | AC28: #NAME? | AD28: #NAME? | AE28: #NAME? | AF28: #NAME? | AG28: #NAME? | AH28: #NAME? | AI28: #NAME?
A29: =IFERROR(__xludf.DUMMYFUNCTION("""COMPUTED_VALUE"""),"宋昆銘") -> 宋昆銘 | B29: =IFERROR(__xludf.DUMMYFUNCTION("""COMPUTED_VALUE"""),"生理男") -> 生理男 | C29: =IFERROR(__xludf.DUMMYFUNCTION("""COMPUTED_VALUE"""),"46-50") -> 46-50 | D29: =IFERROR(__xludf.DUMMYFUNCTION("""COMPUTED_VALUE"""),"臺北市") -> 臺北市 | E29: =IFERROR(__xludf.DUMMYFUNCTION("""COMPUTED_VALUE"""),"媒體出版業") -> 媒體出版業 | F29: {=XLOOKUP(A29,'彼此影業 劇本盲測對象調查 - 盲測初選名單 (已自動連結)'!B:B,'彼此影業 劇本盲測對象調查 - 盲測初選名單 (已自動連結)'!H:J)} -> #NAME? | G29: #NAME? | H29: #NAME? | I29: {=XLOOKUP(A29,#REF!,#REF!)} -> #NAME? | J29: #NAME? | K29: #NAME? | L29: #NAME? | M29: #NAME? | N29: #NAME? | O29: #NAME? | P29: #NAME? | Q29: #NAME? | R29: #NAME? | S29: #NAME? | T29: #NAME? | U29: #NAME? | V29: #NAME? | W29: #NAME? | X29: #NAME? | Y29: #NAME? | Z29: #NAME? | AA29: #NAME? | AB29: #NAME? | AC29: #NAME? | AD29: #NAME? | AE29: #NAME? | AF29: #NAME? | AG29: #NAME? | AH29: #NAME? | AI29: #NAME?
A30: =IFERROR(__xludf.DUMMYFUNCTION("""COMPUTED_VALUE"""),"莊仁豪") -> 莊仁豪 | B30: =IFERROR(__xludf.DUMMYFUNCTION("""COMPUTED_VALUE"""),"生理男") -> 生理男 | C30: =IFERROR(__xludf.DUMMYFUNCTION("""COMPUTED_VALUE"""),"36-40") -> 36-40 | D30: =IFERROR(__xludf.DUMMYFUNCTION("""COMPUTED_VALUE"""),"臺北市") -> 臺北市 | E30: =IFERROR(__xludf.DUMMYFUNCTION("""COMPUTED_VALUE"""),"醫療") -> 醫療 | F30: {=XLOOKUP(A30,'彼此影業 劇本盲測對象調查 - 盲測初選名單 (已自動連結)'!B:B,'彼此影業 劇本盲測對象調查 - 盲測初選名單 (已自動連結)'!H:J)} -> #NAME? | G30: #NAME? | H30: #NAME? | I30: {=XLOOKUP(A30,#REF!,#REF!)} -> #NAME? | J30: #NAME? | K30: #NAME? | L30: #NAME? | M30: #NAME? | N30: #NAME? | O30: #NAME? | P30: #NAME? | Q30: #NAME? | R30: #NAME? | S30: #NAME? | T30: #NAME? | U30: #NAME? | V30: #NAME? | W30: #NAME? | X30: #NAME? | Y30: #NAME? | Z30: #NAME? | AA30: #NAME? | AB30: #NAME? | AC30: #NAME? | AD30: #NAME? | AE30: #NAME? | AF30: #NAME? | AG30: #NAME? | AH30: #NAME? | AI30: #NAME?
A31: =IFERROR(__xludf.DUMMYFUNCTION("""COMPUTED_VALUE"""),"陳婷") -> 陳婷 | B31: =IFERROR(__xludf.DUMMYFUNCTION("""COMPUTED_VALUE"""),"生理女") -> 生理女 | C31: =IFERROR(__xludf.DUMMYFUNCTION("""COMPUTED_VALUE"""),"31-35") -> 31-35 | D31: =IFERROR(__xludf.DUMMYFUNCTION("""COMPUTED_VALUE"""),"臺中市") -> 臺中市 | E31: =IFERROR(__xludf.DUMMYFUNCTION("""COMPUTED_VALUE"""),"心理師") -> 心理師 | F31: {=XLOOKUP(A31,'彼此影業 劇本盲測對象調查 - 盲測初選名單 (已自動連結)'!B:B,'彼此影業 劇本盲測對象調查 - 盲測初選名單 (已自動連結)'!H:J)} -> #NAME? | G31: #NAME? | H31: #NAME? | I31: {=XLOOKUP(A31,#REF!,#REF!)} -> #NAME? | J31: #NAME? | K31: #NAME? | L31: #NAME? | M31: #NAME? | N31: #NAME? | O31: #NAME? | P31: #NAME? | Q31: #NAME? | R31: #NAME? | S31: #NAME? | T31: #NAME? | U31: #NAME? | V31: #NAME? | W31: #NAME? | X31: #NAME? | Y31: #NAME? | Z31: #NAME? | AA31: #NAME? | AB31: #NAME? | AC31: #NAME? | AD31: #NAME? | AE31: #NAME? | AF31: #NAME? | AG31: #NAME? | AH31: #NAME? | AI31: #NAME?
A32: =IFERROR(__xludf.DUMMYFUNCTION("""COMPUTED_VALUE"""),"吳政鴻") -> 吳政鴻 | B32: =IFERROR(__xludf.DUMMYFUNCTION("""COMPUTED_VALUE"""),"生理男") -> 生理男 | C32: =IFERROR(__xludf.DUMMYFUNCTION("""COMPUTED_VALUE"""),"41-45") -> 41-45 | D32: =IFERROR(__xludf.DUMMYFUNCTION("""COMPUTED_VALUE"""),"桃園市") -> 桃園市 | E32: =IFERROR(__xludf.DUMMYFUNCTION("""COMPUTED_VALUE"""),"資訊業") -> 資訊業 | F32: {=XLOOKUP(A32,'彼此影業 劇本盲測對象調查 - 盲測初選名單 (已自動連結)'!B:B,'彼此影業 劇本盲測對象調查 - 盲測初選名單 (已自動連結)'!H:J)} -> #NAME? | G32: #NAME? | H32: #NAME? | I32: {=XLOOKUP(A32,#REF!,#REF!)} -> #NAME? | J32: #NAME? | K32: #NAME? | L32: #NAME? | M32: #NAME? | N32: #NAME? | O32: #NAME? | P32: #NAME? | Q32: #NAME? | R32: #NAME? | S32: #NAME? | T32: #NAME? | U32: #NAME? | V32: #NAME? | W32: #NAME? | X32: #NAME? | Y32: #NAME? | Z32: #NAME? | AA32: #NAME? | AB32: #NAME? | AC32: #NAME? | AD32: #NAME? | AE32: #NAME? | AF32: #NAME? | AG32: #NAME? | AH32: #NAME? | AI32: #NAME?
A33: =IFERROR(__xludf.DUMMYFUNCTION("""COMPUTED_VALUE"""),"丁展譽") -> 丁展譽 | B33: =IFERROR(__xludf.DUMMYFUNCTION("""COMPUTED_VALUE"""),"生理男") -> 生理男 | C33: =IFERROR(__xludf.DUMMYFUNCTION("""COMPUTED_VALUE"""),"36-40") -> 36-40 | D33: =IFERROR(__xludf.DUMMYFUNCTION("""COMPUTED_VALUE"""),"台北市") -> 台北市 | E33: =IFERROR(__xludf.DUMMYFUNCTION("""COMPUTED_VALUE"""),"科技 / 新創 / 網路 / 行銷") -> 科技 / 新創 / 網路 / 行銷 | F33: {=XLOOKUP(A33,'彼此影業 劇本盲測對象調查 - 盲測初選名單 (已自動連結)'!B:B,'彼此影業 劇本盲測對象調查 - 盲測初選名單 (已自動連結)'!H:J)} -> #NAME? | G33: #NAME? | H33: #NAME? | I33: {=XLOOKUP(A33,#REF!,#REF!)} -> #NAME? | J33: #NAME? | K33: #NAME? | L33: #NAME? | M33: #NAME? | N33: #NAME? | O33: #NAME? | P33: #NAME? | Q33: #NAME? | R33: #NAME? | S33: #NAME? | T33: #NAME? | U33: #NAME? | V33: #NAME? | W33: #NAME? | X33: #NAME? | Y33: #NAME? | Z33: #NAME? | AA33: #NAME? | AB33: #NAME? | AC33: #NAME? | AD33: #NAME? | AE33: #NAME? | AF33: #NAME? | AG33: #NAME? | AH33: #NAME? | AI33: #NAME?
A34: =IFERROR(__xludf.DUMMYFUNCTION("""COMPUTED_VALUE"""),"謝嘉芫") -> 謝嘉芫 | B34: =IFERROR(__xludf.DUMMYFUNCTION("""COMPUTED_VALUE"""),"生理男") -> 生理男 | C34: =IFERROR(__xludf.DUMMYFUNCTION("""COMPUTED_VALUE"""),"31-35") -> 31-35 | D34: =IFERROR(__xludf.DUMMYFUNCTION("""COMPUTED_VALUE"""),"新北市") -> 新北市 | E34: =IFERROR(__xludf.DUMMYFUNCTION("""COMPUTED_VALUE"""),"廣告行銷") -> 廣告行銷 | F34: {=XLOOKUP(A34,'彼此影業 劇本盲測對象調查 - 盲測初選名單 (已自動連結)'!B:B,'彼此影業 劇本盲測對象調查 - 盲測初選名單 (已自動連結)'!H:J)} -> #NAME? | G34: #NAME? | H34: #NAME? | I34: {=XLOOKUP(A34,#REF!,#REF!)} -> #NAME? | J34: #NAME? | K34: #NAME? | L34: #NAME? | M34: #NAME? | N34: #NAME? | O34: #NAME? | P34: #NAME? | Q34: #NAME? | R34: #NAME? | S34: #NAME? | T34: #NAME? | U34: #NAME? | V34: #NAME? | W34: #NAME? | X34: #NAME? | Y34: #NAME? | Z34: #NAME? | AA34: #NAME? | AB34: #NAME? | AC34: #NAME? | AD34: #NAME? | AE34: #NAME? | AF34: #NAME? | AG34: #NAME? | AH34: #NAME? | AI34: #NAME?
A35: =IFERROR(__xludf.DUMMYFUNCTION("""COMPUTED_VALUE"""),"陳巧孟") -> 陳巧孟 | B35: =IFERROR(__xludf.DUMMYFUNCTION("""COMPUTED_VALUE"""),"生理女") -> 生理女 | C35: =IFERROR(__xludf.DUMMYFUNCTION("""COMPUTED_VALUE"""),"26-30") -> 26-30 | D35: =IFERROR(__xludf.DUMMYFUNCTION("""COMPUTED_VALUE"""),"台中市") -> 台中市 | E35: =IFERROR(__xludf.DUMMYFUNCTION("""COMPUTED_VALUE"""),"房地產") -> 房地產 | F35: {=XLOOKUP(A35,'彼此影業 劇本盲測對象調查 - 盲測初選名單 (已自動連結)'!B:B,'彼此影業 劇本盲測對象調查 - 盲測初選名單 (已自動連結)'!H:J)} -> #NAME? | G35: #NAME? | H35: #NAME? | I35: {=XLOOKUP(A35,#REF!,#REF!)} -> #NAME? | J35: #NAME? | K35: #NAME? | L35: #NAME? | M35: #NAME? | N35: #NAME? | O35: #NAME? | P35: #NAME? | Q35: #NAME? | R35: #NAME? | S35: #NAME? | T35: #NAME? | U35: #NAME? | V35: #NAME? | W35: #NAME? | X35: #NAME? | Y35: #NAME? | Z35: #NAME? | AA35: #NAME? | AB35: #NAME? | AC35: #NAME? | AD35: #NAME? | AE35: #NAME? | AF35: #NAME? | AG35: #NAME? | AH35: #NAME? | AI35: #NAME?
